Workbook

Sheet GRAFICO
A1: 🗺️ SERVICIO DE MOVILIDAD - CD TOTTUS HUACHIPA
A2: 📍 CD TOTTUS HUACHIPA | Lat: -11.997563 | Long: -76.900062
A4: 📊 ÁREA: | B4: TODOS | D4: STAFF | G4: =IF(B8=0,"⚠️ No hay empleados para: "&B4&" | "&D4,"ÁREA: "&B4&" | TIPO: "&D4&"") -> ÁREA: TODOS | TIPO: STAFF
A6: 📊 RESUMEN | D6: 🏢 DISTANCIA AL CENTRO DE DISTRIBUCIÓN | H6: 🚌 DISTANCIA A PARADEROS MÁS CERCANOS
A7: Métrica | B7: Valor | D7: Clasificación | E7: Empleados | F7: Porcentaje | H7: Clasificación | I7: Empleados | J7: Porcentaje
A8: Total Empleados Analizados | B8: =IF($D$4="TODOS", IF($B$4="TODOS",COUNTA('BD SECOS'!A:A)+COUNTA('BD PPA'!A:A)+COUNTA('BD FRESCOS'!A:A)-3, IF($B$4="SECOS",COUNTA('BD SECOS'!A:A)-1, IF($B$4="PPA",COUNTA('BD PPA'!A:A)-1,COUNTA('BD FRESCOS'!A:A)-1))), IF($B$4="TODOS", COUNTIF('BD SECOS'!AE:AE,$D$4)+COUNTIF('BD PPA'!AK:AK,$D$4)+COUNTIF('BD FRESCOS'!AK:AK,$D$4), IF($B$4="SECOS",COUNTIF('BD SECOS'!AE:AE,$D$4), IF($B$4="PPA",COUNTIF('BD PPA'!AK:AK,$D$4),COUNTIF('BD FRESCOS'!AK:AK,$D$4))))) -> 153 | D8: 🟢 Muy Cerca (0-5 km) | E8: =IF($D$4="TODOS", IF($B$4="TODOS",COUNTIF('BD SECOS'!V:V,"*Muy Cerca*")+COUNTIF('BD PPA'!AB:AB,"*Muy Cerca*")+COUNTIF('BD FRESCOS'!AB:AB,"*Muy Cerca*"), IF($B$4="SECOS",COUNTIF('BD SECOS'!V:V,"*Muy Cerca*"), IF($B$4="PPA",COUNTIF('BD PPA'!AB:AB,"*Muy Cerca*"),COUNTIF('BD FRESCOS'!AB:AB,"*Muy Cerca*")))), IF($B$4="TODOS", COUNTIFS('BD SECOS'!V:V,"*Muy Cerca*",'BD SECOS'!AE:AE,$D$4)+COUNTIFS('BD PPA'!AB:AB,"*Muy Cerca*",'BD PPA'!AK:AK,$D$4)+COUNTIFS('BD FRESCOS'!AB:AB,"*Muy Cerca*",'BD FRESCOS'!AK:AK,$D$4), IF($B$4="SECOS",COUNTIFS('BD SECOS'!V:V,"*Muy Cerca*",'BD SECOS'!AE:AE,$D$4), IF($B$4="PPA",COUNTIFS('BD PPA'!AB:AB,"*Muy Cerca*",'BD PPA'!AK:AK,$D$4),COUNTIFS('BD FRESCOS'!AB:AB,"*Muy Cerca*",'BD FRESCOS'!AK:AK,$D$4))))) -> 18 | F8: =IFERROR(IF($B$8=0,0,E8/$B$8),0) -> 0.11764706 | H8: 🟢 Muy Cerca (0-1 km) | I8: =IF($D$4="TODOS", IF($B$4="TODOS",COUNTIF('BD SECOS'!Z:Z,"*Muy Cerca*")+COUNTIF('BD PPA'!AF:AF,"*Muy Cerca*")+COUNTIF('BD FRESCOS'!AF:AF,"*Muy Cerca*"), IF($B$4="SECOS",COUNTIF('BD SECOS'!Z:Z,"*Muy Cerca*"), IF($B$4="PPA",COUNTIF('BD PPA'!AF:AF,"*Muy Cerca*"),COUNTIF('BD FRESCOS'!AF:AF,"*Muy Cerca*")))), IF($B$4="TODOS", COUNTIFS('BD SECOS'!Z:Z,"*Muy Cerca*",'BD SECOS'!AE:AE,$D$4)+COUNTIFS('BD PPA'!AF:AF,"*Muy Cerca*",'BD PPA'!AK:AK,$D$4)+COUNTIFS('BD FRESCOS'!AF:AF,"*Muy Cerca*",'BD FRESCOS'!AK:AK,$D$4), IF($B$4="SECOS",COUNTIFS('BD SECOS'!Z:Z,"*Muy Cerca*",'BD SECOS'!AE:AE,$D$4), IF($B$4="PPA",COUNTIFS('BD PPA'!AF:AF,"*Muy Cerca*",'BD PPA'!AK:AK,$D$4),COUNTIFS('BD FRESCOS'!AF:AF,"*Muy Cerca*",'BD FRESCOS'!AK:AK,$D$4))))) -> 57 | J8: =IFERROR(IF($B$8=0,0,I8/$B$8),0) -> 0.37254902
A9: Total Distritos | B9: {=IFERROR(IF($D$4="TODOS",IF($B$4="TODOS",ROWS(_xlfn.UNIQUE(_xlfn.VSTACK('BD SECOS'!Q2:Q455,'BD PPA'!U2:U386,'BD FRESCOS'!U2:U236))),IF($B$4="SECOS",SUMPRODUCT(1/COUNTIF('BD SECOS'!Q2:Q455,'BD SECOS'!Q2:Q455)),IF($B$4="PPA",SUMPRODUCT(1/COUNTIF('BD PPA'!U2:U386,'BD PPA'!U2:U386)),SUMPRODUCT(1/COUNTIF('BD FRESCOS'!U2:U236,'BD FRESCOS'!U2:U236))))),IF($B$4="TODOS",ROWS(_xlfn.UNIQUE(_xlfn._xlws.FILTER(_xlfn.VSTACK('BD SECOS'!Q2:Q455,'BD PPA'!U2:U386,'BD FRESCOS'!U2:U236),_xlfn.VSTACK('BD SECOS'!AE2:AE455,'BD PPA'!AK2:AK386,'BD FRESCOS'!AK2:AK236)=$D$4))),IF($B$4="SECOS",ROWS(_xlfn.UNIQUE(_xlfn._xlws.FILTER('BD SECOS'!Q2:Q455,'BD SECOS'!AE2:AE455=$D$4))),IF($B$4="PPA",ROWS(_xlfn.UNIQUE(_xlfn._xlws.FILTER('BD PPA'!U2:U386,'BD PPA'!AK2:AK386=$D$4))),ROWS(_xlfn.UNIQUE(_xlfn._xlws.FILTER('BD FRESCOS'!U2:U236,'BD FRESCOS'!AK2:AK236=$D$4))))))),0)} -> 33 | D9: 🟡 Cerca (5-10 km) | E9: =IF($D$4="TODOS", IF($B$4="TODOS",COUNTIF('BD SECOS'!V:V,"*Cerca (5*")+COUNTIF('BD PPA'!AB:AB,"*Cerca (5*")+COUNTIF('BD FRESCOS'!AB:AB,"*Cerca (5*"), IF($B$4="SECOS",COUNTIF('BD SECOS'!V:V,"*Cerca (5*"), IF($B$4="PPA",COUNTIF('BD PPA'!AB:AB,"*Cerca (5*"),COUNTIF('BD FRESCOS'!AB:AB,"*Cerca (5*")))), IF($B$4="TODOS", COUNTIFS('BD SECOS'!V:V,"*Cerca (5*",'BD SECOS'!AE:AE,$D$4)+COUNTIFS('BD PPA'!AB:AB,"*Cerca (5*",'BD PPA'!AK:AK,$D$4)+COUNTIFS('BD FRESCOS'!AB:AB,"*Cerca (5*",'BD FRESCOS'!AK:AK,$D$4), IF($B$4="SECOS",COUNTIFS('BD SECOS'!V:V,"*Cerca (5*",'BD SECOS'!AE:AE,$D$4), IF($B$4="PPA",COUNTIFS('BD PPA'!AB:AB,"*Cerca (5*",'BD PPA'!AK:AK,$D$4),COUNTIFS('BD FRESCOS'!AB:AB,"*Cerca (5*",'BD FRESCOS'!AK:AK,$D$4))))) -> 30 | F9: =IFERROR(IF($B$8=0,0,E9/$B$8),0) -> 0.19607843 | H9: 🟡 Cerca (1-3 km) | I9: =IF($D$4="TODOS", IF($B$4="TODOS",COUNTIF('BD SECOS'!Z:Z,"*Cerca (1*")+COUNTIF('BD PPA'!AF:AF,"*Cerca (1*")+COUNTIF('BD FRESCOS'!AF:AF,"*Cerca (1*"), IF($B$4="SECOS",COUNTIF('BD SECOS'!Z:Z,"*Cerca (1*"), IF($B$4="PPA",COUNTIF('BD PPA'!AF:AF,"*Cerca (1*"),COUNTIF('BD FRESCOS'!AF:AF,"*Cerca (1*")))), IF($B$4="TODOS", COUNTIFS('BD SECOS'!Z:Z,"*Cerca (1*",'BD SECOS'!AE:AE,$D$4)+COUNTIFS('BD PPA'!AF:AF,"*Cerca (1*",'BD PPA'!AK:AK,$D$4)+COUNTIFS('BD FRESCOS'!AF:AF,"*Cerca (1*",'BD FRESCOS'!AK:AK,$D$4), IF($B$4="SECOS",COUNTIFS('BD SECOS'!Z:Z,"*Cerca (1*",'BD SECOS'!AE:AE,$D$4), IF($B$4="PPA",COUNTIFS('BD PPA'!AF:AF,"*Cerca (1*",'BD PPA'!AK:AK,$D$4),COUNTIFS('BD FRESCOS'!AF:AF,"*Cerca (1*",'BD FRESCOS'!AK:AK,$D$4))))) -> 70 | J9: =IFERROR(IF($B$8=0,0,I9/$B$8),0) -> 0.45751634
A10: Distancia Promedio al CD | B10: {=IFERROR(IF($D$4="TODOS",IF($B$4="TODOS",AVERAGE('BD SECOS'!U2:U455,'BD PPA'!AA2:AA386,'BD FRESCOS'!AA2:AA236),IF($B$4="SECOS",AVERAGE('BD SECOS'!U2:U455),IF($B$4="PPA",AVERAGE('BD PPA'!AA2:AA386),AVERAGE('BD FRESCOS'!AA2:AA236)))),IF($B$4="TODOS",(SUMPRODUCT(('BD SECOS'!AE2:AE455=$D$4)*'BD SECOS'!U2:U455)+SUMPRODUCT(('BD PPA'!AK2:AK386=$D$4)*'BD PPA'!AA2:AA386)+SUMPRODUCT(('BD FRESCOS'!AK2:AK236=$D$4)*'BD FRESCOS'!AA2:AA236))/(COUNTIF('BD SECOS'!AE2:AE455,$D$4)+COUNTIF('BD PPA'!AK2:AK386,$D$4)+COUNTIF('BD FRESCOS'!AK2:AK236,$D$4)),IF($B$4="SECOS",AVERAGEIF('BD SECOS'!AE2:AE455,$D$4,'BD SECOS'!U2:U455),IF($B$4="PPA",AVERAGEIF('BD PPA'!AK2:AK386,$D$4,'BD PPA'!AA2:AA386),AVERAGEIF('BD FRESCOS'!AK2:AK236,$D$4,'BD FRESCOS'!AA2:AA236))))),"N/A")} -> 13.941503 | D10: 🟠 Moderada (10-20 km) | E10: =IF($D$4="TODOS", IF($B$4="TODOS",COUNTIF('BD SECOS'!V:V,"*Moderada*")+COUNTIF('BD PPA'!AB:AB,"*Moderada*")+COUNTIF('BD FRESCOS'!AB:AB,"*Moderada*"), IF($B$4="SECOS",COUNTIF('BD SECOS'!V:V,"*Moderada*"), IF($B$4="PPA",COUNTIF('BD PPA'!AB:AB,"*Moderada*"),COUNTIF('BD FRESCOS'!AB:AB,"*Moderada*")))), IF($B$4="TODOS", COUNTIFS('BD SECOS'!V:V,"*Moderada*",'BD SECOS'!AE:AE,$D$4)+COUNTIFS('BD PPA'!AB:AB,"*Moderada*",'BD PPA'!AK:AK,$D$4)+COUNTIFS('BD FRESCOS'!AB:AB,"*Moderada*",'BD FRESCOS'!AK:AK,$D$4), IF($B$4="SECOS",COUNTIFS('BD SECOS'!V:V,"*Moderada*",'BD SECOS'!AE:AE,$D$4), IF($B$4="PPA",COUNTIFS('BD PPA'!AB:AB,"*Moderada*",'BD PPA'!AK:AK,$D$4),COUNTIFS('BD FRESCOS'!AB:AB,"*Moderada*",'BD FRESCOS'!AK:AK,$D$4))))) -> 72 | F10: =IFERROR(IF($B$8=0,0,E10/$B$8),0) -> 0.47058824 | H10: 🟠 Moderada (3-5 km) | I10: =IF($D$4="TODOS", IF($B$4="TODOS",COUNTIF('BD SECOS'!Z:Z,"*Moderada*")+COUNTIF('BD PPA'!AF:AF,"*Moderada*")+COUNTIF('BD FRESCOS'!AF:AF,"*Moderada*"), IF($B$4="SECOS",COUNTIF('BD SECOS'!Z:Z,"*Moderada*"), IF($B$4="PPA",COUNTIF('BD PPA'!AF:AF,"*Moderada*"),COUNTIF('BD FRESCOS'!AF:AF,"*Moderada*")))), IF($B$4="TODOS", COUNTIFS('BD SECOS'!Z:Z,"*Moderada*",'BD SECOS'!AE:AE,$D$4)+COUNTIFS('BD PPA'!AF:AF,"*Moderada*",'BD PPA'!AK:AK,$D$4)+COUNTIFS('BD FRESCOS'!AF:AF,"*Moderada*",'BD FRESCOS'!AK:AK,$D$4), IF($B$4="SECOS",COUNTIFS('BD SECOS'!Z:Z,"*Moderada*",'BD SECOS'!AE:AE,$D$4), IF($B$4="PPA",COUNTIFS('BD PPA'!AF:AF,"*Moderada*",'BD PPA'!AK:AK,$D$4),COUNTIFS('BD FRESCOS'!AF:AF,"*Moderada*",'BD FRESCOS'!AK:AK,$D$4))))) -> 15 | J10: =IFERROR(IF($B$8=0,0,I10/$B$8),0) -> 0.098039216
A11: Distancia Promedio a Paradero | B11: {=IFERROR(IF($D$4="TODOS",IF($B$4="TODOS",AVERAGE('BD SECOS'!Y2:Y455,'BD PPA'!AE2:AE386,'BD FRESCOS'!AE2:AE236),IF($B$4="SECOS",AVERAGE('BD SECOS'!Y2:Y455),IF($B$4="PPA",AVERAGE('BD PPA'!AE2:AE386),AVERAGE('BD FRESCOS'!AE2:AE236)))),IF($B$4="TODOS",(SUMPRODUCT(('BD SECOS'!AE2:AE455=$D$4)*'BD SECOS'!Y2:Y455)+SUMPRODUCT(('BD PPA'!AK2:AK386=$D$4)*'BD PPA'!AE2:AE386)+SUMPRODUCT(('BD FRESCOS'!AK2:AK236=$D$4)*'BD FRESCOS'!AE2:AE236))/(COUNTIF('BD SECOS'!AE2:AE455,$D$4)+COUNTIF('BD PPA'!AK2:AK386,$D$4)+COUNTIF('BD FRESCOS'!AK2:AK236,$D$4)),IF($B$4="SECOS",AVERAGEIF('BD SECOS'!AE2:AE455,$D$4,'BD SECOS'!Y2:Y455),IF($B$4="PPA",AVERAGEIF('BD PPA'!AK2:AK386,$D$4,'BD PPA'!AE2:AE386),AVERAGEIF('BD FRESCOS'!AK2:AK236,$D$4,'BD FRESCOS'!AE2:AE236))))),"N/A")} -> 1.9980392 | D11: 🔴 Lejos (>20 km) | E11: =IF($D$4="TODOS", IF($B$4="TODOS",COUNTIF('BD SECOS'!V:V,"*Lejos*")+COUNTIF('BD PPA'!AB:AB,"*Lejos*")+COUNTIF('BD FRESCOS'!AB:AB,"*Lejos*"), IF($B$4="SECOS",COUNTIF('BD SECOS'!V:V,"*Lejos*"), IF($B$4="PPA",COUNTIF('BD PPA'!AB:AB,"*Lejos*"),COUNTIF('BD FRESCOS'!AB:AB,"*Lejos*")))), IF($B$4="TODOS", COUNTIFS('BD SECOS'!V:V,"*Lejos*",'BD SECOS'!AE:AE,$D$4)+COUNTIFS('BD PPA'!AB:AB,"*Lejos*",'BD PPA'!AK:AK,$D$4)+COUNTIFS('BD FRESCOS'!AB:AB,"*Lejos*",'BD FRESCOS'!AK:AK,$D$4), IF($B$4="SECOS",COUNTIFS('BD SECOS'!V:V,"*Lejos*",'BD SECOS'!AE:AE,$D$4), IF($B$4="PPA",COUNTIFS('BD PPA'!AB:AB,"*Lejos*",'BD PPA'!AK:AK,$D$4),COUNTIFS('BD FRESCOS'!AB:AB,"*Lejos*",'BD FRESCOS'!AK:AK,$D$4))))) -> 33 | F11: =IFERROR(IF($B$8=0,0,E11/$B$8),0) -> 0.21568627 | H11: 🔴 Lejos (>5 km) | I11: =IF($D$4="TODOS", IF($B$4="TODOS",COUNTIF('BD SECOS'!Z:Z,"*Lejos*")+COUNTIF('BD PPA'!AF:AF,"*Lejos*")+COUNTIF('BD FRESCOS'!AF:AF,"*Lejos*"), IF($B$4="SECOS",COUNTIF('BD SECOS'!Z:Z,"*Lejos*"), IF($B$4="PPA",COUNTIF('BD PPA'!AF:AF,"*Lejos*"),COUNTIF('BD FRESCOS'!AF:AF,"*Lejos*")))), IF($B$4="TODOS", COUNTIFS('BD SECOS'!Z:Z,"*Lejos*",'BD SECOS'!AE:AE,$D$4)+COUNTIFS('BD PPA'!AF:AF,"*Lejos*",'BD PPA'!AK:AK,$D$4)+COUNTIFS('BD FRESCOS'!AF:AF,"*Lejos*",'BD FRESCOS'!AK:AK,$D$4), IF($B$4="SECOS",COUNTIFS('BD SECOS'!Z:Z,"*Lejos*",'BD SECOS'!AE:AE,$D$4), IF($B$4="PPA",COUNTIFS('BD PPA'!AF:AF,"*Lejos*",'BD PPA'!AK:AK,$D$4),COUNTIFS('BD FRESCOS'!AF:AF,"*Lejos*",'BD FRESCOS'!AK:AK,$D$4))))) -> 11 | J11: =IFERROR(IF($B$8=0,0,I11/$B$8),0) -> 0.071895425
A12: Total Rutas Utilizadas (según filtros) | B12: =COUNTIF($W$98:$W$111,">0") -> 0
A17: 🏆 TOP 10 DISTRITOS CON MAYOR VOLUMEN DE EMPLEADOS | F17: 🚌 RUTAS DISPONIBLES | K17: 📍 TOP 10 PARADEROS MÁS CERCANOS A EMPLEADOS
A18: # | B18: Distrito | C18: Empleados | D18: Porcentaje | F18: # | G18: Ruta | H18: Empleados | I18: % Total | K18: # | L18: Paradero | M18: Ruta | N18: Empleados | O18: % Total
A19: 1 | B19: =IFERROR(INDEX(Distritos!$H$7:$H$51,MATCH(SMALL(Distritos!$J$7:$J$51,1),Distritos!$J$7:$J$51,0)),"") -> Ate | C19: =IFERROR(INDEX(Distritos!$I$7:$I$51,MATCH(SMALL(Distritos!$J$7:$J$51,1),Distritos!$J$7:$J$51,0)),0) -> 25 | D19: =IFERROR(IF(OR($B$8=0,C19="",C19=0),0,C19/$B$8),0) -> 0.16339869 | F19: 1 | G19: =IFERROR(INDEX(Distritos!$L$7:$L$20,MATCH(SMALL(Distritos!$N$7:$N$20,1),Distritos!$N$7:$N$20,0)),"") -> RUTA 7 | H19: =IFERROR(INDEX(Distritos!$M$7:$M$20,MATCH(SMALL(Distritos!$N$7:$N$20,1),Distritos!$N$7:$N$20,0)),0) -> 29 | I19: =IFERROR(IF(OR($B$8=0,H19="",H19=0),0,H19/$B$8),0) -> 0.18954248 | K19: 1 | L19: =IFERROR(INDEX(Distritos!$O$7:$O$46,MATCH(SMALL(Distritos!$R$7:$R$46,1),Distritos!$R$7:$R$46,0)),"") -> Paradero Arco San Antonio | M19: =IFERROR(INDEX(Distritos!$P$7:$P$46,MATCH(SMALL(Distritos!$R$7:$R$46,1),Distritos!$R$7:$R$46,0)),"") -> RUTA 2 | N19: =IFERROR(INDEX(Distritos!$Q$7:$Q$46,MATCH(SMALL(Distritos!$R$7:$R$46,1),Distritos!$R$7:$R$46,0)),0) -> 8 | O19: =IFERROR(IF(OR($B$8=0,N19="",N19=0),0,N19/$B$8),0) -> 0.052287582
A20: 2 | B20: =IFERROR(INDEX(Distritos!$H$7:$H$51,MATCH(SMALL(Distritos!$J$7:$J$51,2),Distritos!$J$7:$J$51,0)),"") -> San Juan De Lurigancho | C20: =IFERROR(INDEX(Distritos!$I$7:$I$51,MATCH(SMALL(Distritos!$J$7:$J$51,2),Distritos!$J$7:$J$51,0)),0) -> 22 | D20: =IFERROR(IF(OR($B$8=0,C20="",C20=0),0,C20/$B$8),0) -> 0.14379085 | F20: 2 | G20: =IFERROR(INDEX(Distritos!$L$7:$L$20,MATCH(SMALL(Distritos!$N$7:$N$20,2),Distritos!$N$7:$N$20,0)),"") -> RUTA 4A | H20: =IFERROR(INDEX(Distritos!$M$7:$M$20,MATCH(SMALL(Distritos!$N$7:$N$20,2),Distritos!$N$7:$N$20,0)),0) -> 18 | I20: =IFERROR(IF(OR($B$8=0,H20="",H20=0),0,H20/$B$8),0) -> 0.11764706 | K20: 2 | L20: =IFERROR(INDEX(Distritos!$O$7:$O$46,MATCH(SMALL(Distritos!$R$7:$R$46,2),Distritos!$R$7:$R$46,0)),"") -> Paradero Berlín con Javier prado (cruzando el semáforo) aplica solo al ingreso. | M20: =IFERROR(INDEX(Distritos!$P$7:$P$46,MATCH(SMALL(Distritos!$R$7:$R$46,2),Distritos!$R$7:$R$46,0)),"") -> RUTA 4A | N20: =IFERROR(INDEX(Distritos!$Q$7:$Q$46,MATCH(SMALL(Distritos!$R$7:$R$46,2),Distritos!$R$7:$R$46,0)),0) -> 7 | O20: =IFERROR(IF(OR($B$8=0,N20="",N20=0),0,N20/$B$8),0) -> 0.045751634
A21: 3 | B21: =IFERROR(INDEX(Distritos!$H$7:$H$51,MATCH(SMALL(Distritos!$J$7:$J$51,3),Distritos!$J$7:$J$51,0)),"") -> Lurigancho | C21: =IFERROR(INDEX(Distritos!$I$7:$I$51,MATCH(SMALL(Distritos!$J$7:$J$51,3),Distritos!$J$7:$J$51,0)),0) -> 21 | D21: =IFERROR(IF(OR($B$8=0,C21="",C21=0),0,C21/$B$8),0) -> 0.1372549 | F21: 3 | G21: =IFERROR(INDEX(Distritos!$L$7:$L$20,MATCH(SMALL(Distritos!$N$7:$N$20,3),Distritos!$N$7:$N$20,0)),"") -> RUTA 8 | H21: =IFERROR(INDEX(Distritos!$M$7:$M$20,MATCH(SMALL(Distritos!$N$7:$N$20,3),Distritos!$N$7:$N$20,0)),0) -> 17 | I21: =IFERROR(IF(OR($B$8=0,H21="",H21=0),0,H21/$B$8),0) -> 0.11111111 | K21: 3 | L21: =IFERROR(INDEX(Distritos!$O$7:$O$46,MATCH(SMALL(Distritos!$R$7:$R$46,3),Distritos!$R$7:$R$46,0)),"") -> Real Plaza Puruchuco (Grifo Primax) | M21: =IFERROR(INDEX(Distritos!$P$7:$P$46,MATCH(SMALL(Distritos!$R$7:$R$46,3),Distritos!$R$7:$R$46,0)),"") -> RUTA 4A | N21: =IFERROR(INDEX(Distritos!$Q$7:$Q$46,MATCH(SMALL(Distritos!$R$7:$R$46,3),Distritos!$R$7:$R$46,0)),0) -> 5 | O21: =IFERROR(IF(OR($B$8=0,N21="",N21=0),0,N21/$B$8),0) -> 0.032679739
A22: 4 | B22: =IFERROR(INDEX(Distritos!$H$7:$H$51,MATCH(SMALL(Distritos!$J$7:$J$51,4),Distritos!$J$7:$J$51,0)),"") -> Lima | C22: =IFERROR(INDEX(Distritos!$I$7:$I$51,MATCH(SMALL(Distritos!$J$7:$J$51,4),Distritos!$J$7:$J$51,0)),0) -> 10 | D22: =IFERROR(IF(OR($B$8=0,C22="",C22=0),0,C22/$B$8),0) -> 0.065359477 | F22: 4 | G22: =IFERROR(INDEX(Distritos!$L$7:$L$20,MATCH(SMALL(Distritos!$N$7:$N$20,4),Distritos!$N$7:$N$20,0)),"") -> RUTA 5B | H22: =IFERROR(INDEX(Distritos!$M$7:$M$20,MATCH(SMALL(Distritos!$N$7:$N$20,4),Distritos!$N$7:$N$20,0)),0) -> 12 | I22: =IFERROR(IF(OR($B$8=0,H22="",H22=0),0,H22/$B$8),0) -> 0.078431373 | K22: 4 | L22: =IFERROR(INDEX(Distritos!$O$7:$O$46,MATCH(SMALL(Distritos!$R$7:$R$46,4),Distritos!$R$7:$R$46,0)),"") -> Real Plaza Puruchuco (Grifo Primax) | M22: =IFERROR(INDEX(Distritos!$P$7:$P$46,MATCH(SMALL(Distritos!$R$7:$R$46,4),Distritos!$R$7:$R$46,0)),"") -> RUTA 4A | N22: =IFERROR(INDEX(Distritos!$Q$7:$Q$46,MATCH(SMALL(Distritos!$R$7:$R$46,4),Distritos!$R$7:$R$46,0)),0) -> 5 | O22: =IFERROR(IF(OR($B$8=0,N22="",N22=0),0,N22/$B$8),0) -> 0.032679739
A23: 5 | B23: =IFERROR(INDEX(Distritos!$H$7:$H$51,MATCH(SMALL(Distritos!$J$7:$J$51,5),Distritos!$J$7:$J$51,0)),"") -> Santiago De Surco | C23: =IFERROR(INDEX(Distritos!$I$7:$I$51,MATCH(SMALL(Distritos!$J$7:$J$51,5),Distritos!$J$7:$J$51,0)),0) -> 7 | D23: =IFERROR(IF(OR($B$8=0,C23="",C23=0),0,C23/$B$8),0) -> 0.045751634 | F23: 5 | G23: =IFERROR(INDEX(Distritos!$L$7:$L$20,MATCH(SMALL(Distritos!$N$7:$N$20,5),Distritos!$N$7:$N$20,0)),"") -> RUTA 3 | H23: =IFERROR(INDEX(Distritos!$M$7:$M$20,MATCH(SMALL(Distritos!$N$7:$N$20,5),Distritos!$N$7:$N$20,0)),0) -> 11 | I23: =IFERROR(IF(OR($B$8=0,H23="",H23=0),0,H23/$B$8),0) -> 0.071895425 | K23: 5 | L23: =IFERROR(INDEX(Distritos!$O$7:$O$46,MATCH(SMALL(Distritos!$R$7:$R$46,5),Distritos!$R$7:$R$46,0)),"") -> Real Plaza Puruchuco (Grifo Primax) | M23: =IFERROR(INDEX(Distritos!$P$7:$P$46,MATCH(SMALL(Distritos!$R$7:$R$46,5),Distritos!$R$7:$R$46,0)),"") -> RUTA 4A | N23: =IFERROR(INDEX(Distritos!$Q$7:$Q$46,MATCH(SMALL(Distritos!$R$7:$R$46,5),Distritos!$R$7:$R$46,0)),0) -> 5 | O23: =IFERROR(IF(OR($B$8=0,N23="",N23=0),0,N23/$B$8),0) -> 0.032679739
A24: 6 | B24: =IFERROR(INDEX(Distritos!$H$7:$H$51,MATCH(SMALL(Distritos!$J$7:$J$51,6),Distritos!$J$7:$J$51,0)),"") -> Callao | C24: =IFERROR(INDEX(Distritos!$I$7:$I$51,MATCH(SMALL(Distritos!$J$7:$J$51,6),Distritos!$J$7:$J$51,0)),0) -> 6 | D24: =IFERROR(IF(OR($B$8=0,C24="",C24=0),0,C24/$B$8),0) -> 0.039215686 | F24: 6 | G24: =IFERROR(INDEX(Distritos!$L$7:$L$20,MATCH(SMALL(Distritos!$N$7:$N$20,6),Distritos!$N$7:$N$20,0)),"") -> RUTA 3 | H24: =IFERROR(INDEX(Distritos!$M$7:$M$20,MATCH(SMALL(Distritos!$N$7:$N$20,6),Distritos!$N$7:$N$20,0)),0) -> 11 | I24: =IFERROR(IF(OR($B$8=0,H24="",H24=0),0,H24/$B$8),0) -> 0.071895425 | K24: 6 | L24: =IFERROR(INDEX(Distritos!$O$7:$O$46,MATCH(SMALL(Distritos!$R$7:$R$46,6),Distritos!$R$7:$R$46,0)),"") -> Paradero Rompemuelle | M24: =IFERROR(INDEX(Distritos!$P$7:$P$46,MATCH(SMALL(Distritos!$R$7:$R$46,6),Distritos!$R$7:$R$46,0)),"") -> RUTA 3 | N24: =IFERROR(INDEX(Distritos!$Q$7:$Q$46,MATCH(SMALL(Distritos!$R$7:$R$46,6),Distritos!$R$7:$R$46,0)),0) -> 4 | O24: =IFERROR(IF(OR($B$8=0,N24="",N24=0),0,N24/$B$8),0) -> 0.026143791
A25: 7 | B25: =IFERROR(INDEX(Distritos!$H$7:$H$51,MATCH(SMALL(Distritos!$J$7:$J$51,7),Distritos!$J$7:$J$51,0)),"") -> Los Olivos | C25: =IFERROR(INDEX(Distritos!$I$7:$I$51,MATCH(SMALL(Distritos!$J$7:$J$51,7),Distritos!$J$7:$J$51,0)),0) -> 6 | D25: =IFERROR(IF(OR($B$8=0,C25="",C25=0),0,C25/$B$8),0) -> 0.039215686 | F25: 7 | G25: =IFERROR(INDEX(Distritos!$L$7:$L$20,MATCH(SMALL(Distritos!$N$7:$N$20,7),Distritos!$N$7:$N$20,0)),"") -> RUTA 3 | H25: =IFERROR(INDEX(Distritos!$M$7:$M$20,MATCH(SMALL(Distritos!$N$7:$N$20,7),Distritos!$N$7:$N$20,0)),0) -> 11 | I25: =IFERROR(IF(OR($B$8=0,H25="",H25=0),0,H25/$B$8),0) -> 0.071895425 | K25: 7 | L25: =IFERROR(INDEX(Distritos!$O$7:$O$46,MATCH(SMALL(Distritos!$R$7:$R$46,7),Distritos!$R$7:$R$46,0)),"") -> Paradero Rompemuelle | M25: =IFERROR(INDEX(Distritos!$P$7:$P$46,MATCH(SMALL(Distritos!$R$7:$R$46,7),Distritos!$R$7:$R$46,0)),"") -> RUTA 3 | N25: =IFERROR(INDEX(Distritos!$Q$7:$Q$46,MATCH(SMALL(Distritos!$R$7:$R$46,7),Distritos!$R$7:$R$46,0)),0) -> 4 | O25: =IFERROR(IF(OR($B$8=0,N25="",N25=0),0,N25/$B$8),0) -> 0.026143791
A26: 8 | B26: =IFERROR(INDEX(Distritos!$H$7:$H$51,MATCH(SMALL(Distritos!$J$7:$J$51,8),Distritos!$J$7:$J$51,0)),"") -> Carabayllo | C26: =IFERROR(INDEX(Distritos!$I$7:$I$51,MATCH(SMALL(Distritos!$J$7:$J$51,8),Distritos!$J$7:$J$51,0)),0) -> 4 | D26: =IFERROR(IF(OR($B$8=0,C26="",C26=0),0,C26/$B$8),0) -> 0.026143791 | F26: 8 | G26: =IFERROR(INDEX(Distritos!$L$7:$L$20,MATCH(SMALL(Distritos!$N$7:$N$20,8),Distritos!$N$7:$N$20,0)),"") -> RUTA 4B | H26: =IFERROR(INDEX(Distritos!$M$7:$M$20,MATCH(SMALL(Distritos!$N$7:$N$20,8),Distritos!$N$7:$N$20,0)),0) -> 10 | I26: =IFERROR(IF(OR($B$8=0,H26="",H26=0),0,H26/$B$8),0) -> 0.065359477 | K26: 8 | L26: =IFERROR(INDEX(Distritos!$O$7:$O$46,MATCH(SMALL(Distritos!$R$7:$R$46,8),Distritos!$R$7:$R$46,0)),"") -> Paradero Rompemuelle | M26: =IFERROR(INDEX(Distritos!$P$7:$P$46,MATCH(SMALL(Distritos!$R$7:$R$46,8),Distritos!$R$7:$R$46,0)),"") -> RUTA 3 | N26: =IFERROR(INDEX(Distritos!$Q$7:$Q$46,MATCH(SMALL(Distritos!$R$7:$R$46,8),Distritos!$R$7:$R$46,0)),0) -> 4 | O26: =IFERROR(IF(OR($B$8=0,N26="",N26=0),0,N26/$B$8),0) -> 0.026143791
A27: 9 | B27: =IFERROR(INDEX(Distritos!$H$7:$H$51,MATCH(SMALL(Distritos!$J$7:$J$51,9),Distritos!$J$7:$J$51,0)),"") -> Chaclacayo | C27: =IFERROR(INDEX(Distritos!$I$7:$I$51,MATCH(SMALL(Distritos!$J$7:$J$51,9),Distritos!$J$7:$J$51,0)),0) -> 4 | D27: =IFERROR(IF(OR($B$8=0,C27="",C27=0),0,C27/$B$8),0) -> 0.026143791 | F27: 9 | G27: =IFERROR(INDEX(Distritos!$L$7:$L$20,MATCH(SMALL(Distritos!$N$7:$N$20,9),Distritos!$N$7:$N$20,0)),"") -> RUTA 2 | H27: =IFERROR(INDEX(Distritos!$M$7:$M$20,MATCH(SMALL(Distritos!$N$7:$N$20,9),Distritos!$N$7:$N$20,0)),0) -> 8 | I27: =IFERROR(IF(OR($B$8=0,H27="",H27=0),0,H27/$B$8),0) -> 0.052287582 | K27: 9 | L27: =IFERROR(INDEX(Distritos!$O$7:$O$46,MATCH(SMALL(Distritos!$R$7:$R$46,9),Distritos!$R$7:$R$46,0)),"") -> Paradero Rompemuelle | M27: =IFERROR(INDEX(Distritos!$P$7:$P$46,MATCH(SMALL(Distritos!$R$7:$R$46,9),Distritos!$R$7:$R$46,0)),"") -> RUTA 3 | N27: =IFERROR(INDEX(Distritos!$Q$7:$Q$46,MATCH(SMALL(Distritos!$R$7:$R$46,9),Distritos!$R$7:$R$46,0)),0) -> 4 | O27: =IFERROR(IF(OR($B$8=0,N27="",N27=0),0,N27/$B$8),0) -> 0.026143791
A28: 10 | B28: =IFERROR(INDEX(Distritos!$H$7:$H$51,MATCH(SMALL(Distritos!$J$7:$J$51,10),Distritos!$J$7:$J$51,0)),"") -> San Juan De Miraflores | C28: =IFERROR(INDEX(Distritos!$I$7:$I$51,MATCH(SMALL(Distritos!$J$7:$J$51,10),Distritos!$J$7:$J$51,0)),0) -> 4 | D28: =IFERROR(IF(OR($B$8=0,C28="",C28=0),0,C28/$B$8),0) -> 0.026143791 | F28: 10 | G28: =IFERROR(INDEX(Distritos!$L$7:$L$20,MATCH(SMALL(Distritos!$N$7:$N$20,10),Distritos!$N$7:$N$20,0)),"") -> RUTA 2 | H28: =IFERROR(INDEX(Distritos!$M$7:$M$20,MATCH(SMALL(Distritos!$N$7:$N$20,10),Distritos!$N$7:$N$20,0)),0) -> 8 | I28: =IFERROR(IF(OR($B$8=0,H28="",H28=0),0,H28/$B$8),0) -> 0.052287582 | K28: 10 | L28: =IFERROR(INDEX(Distritos!$O$7:$O$46,MATCH(SMALL(Distritos!$R$7:$R$46,10),Distritos!$R$7:$R$46,0)),"") -> Paradero Rompemuelle | M28: =IFERROR(INDEX(Distritos!$P$7:$P$46,MATCH(SMALL(Distritos!$R$7:$R$46,10),Distritos!$R$7:$R$46,0)),"") -> RUTA 3 | N28: =IFERROR(INDEX(Distritos!$Q$7:$Q$46,MATCH(SMALL(Distritos!$R$7:$R$46,10),Distritos!$R$7:$R$46,0)),0) -> 4 | O28: =IFERROR(IF(OR($B$8=0,N28="",N28=0),0,N28/$B$8),0) -> 0.026143791
F29: 11 | G29: =IFERROR(INDEX(Distritos!$L$7:$L$20,MATCH(SMALL(Distritos!$N$7:$N$20,11),Distritos!$N$7:$N$20,0)),"") -> RUTA 6A | H29: =IFERROR(INDEX(Distritos!$M$7:$M$20,MATCH(SMALL(Distritos!$N$7:$N$20,11),Distritos!$N$7:$N$20,0)),0) -> 7 | I29: =IFERROR(IF(OR($B$8=0,H29="",H29=0),0,H29/$B$8),0) -> 0.045751634
F30: 12 | G30: =IFERROR(INDEX(Distritos!$L$7:$L$20,MATCH(SMALL(Distritos!$N$7:$N$20,12),Distritos!$N$7:$N$20,0)),"") -> RUTA 6C | H30: =IFERROR(INDEX(Distritos!$M$7:$M$20,MATCH(SMALL(Distritos!$N$7:$N$20,12),Distritos!$N$7:$N$20,0)),0) -> 5 | I30: =IFERROR(IF(OR($B$8=0,H30="",H30=0),0,H30/$B$8),0) -> 0.032679739
F31: 13 | G31: =IFERROR(INDEX(Distritos!$L$7:$L$20,MATCH(SMALL(Distritos!$N$7:$N$20,13),Distritos!$N$7:$N$20,0)),"") -> RUTA 1 | H31: =IFERROR(INDEX(Distritos!$M$7:$M$20,MATCH(SMALL(Distritos!$N$7:$N$20,13),Distritos!$N$7:$N$20,0)),0) -> 4 | I31: =IFERROR(IF(OR($B$8=0,H31="",H31=0),0,H31/$B$8),0) -> 0.026143791
F32: 14 | G32: =IFERROR(INDEX(Distritos!$L$7:$L$20,MATCH(SMALL(Distritos!$N$7:$N$20,14),Distritos!$N$7:$N$20,0)),"") -> RUTA 5C | H32: =IFERROR(INDEX(Distritos!$M$7:$M$20,MATCH(SMALL(Distritos!$N$7:$N$20,14),Distritos!$N$7:$N$20,0)),0) -> 2 | I32: =IFERROR(IF(OR($B$8=0,H32="",H32=0),0,H32/$B$8),0) -> 0.013071895
A37: 🏘️ ANÁLISIS DETALLADO POR DISTRITO
A38: # | B38: Distrito | C38: Empleados | D38: % Total | E38: Dist. Prom. CD (km) | F38: Clasif. CD | G38: Dist. Prom. Paradero (km) | H38: Clasif. Paradero | I38: Ruta Principal | J38: Observación
A39: =IF(OR($B$8=0,C39="",C39=0),"",1) -> 1 | B39: =IF($B$8=0,"",IFERROR(IF(INDEX(Distritos!$I$7:$I$66,MATCH(SMALL(Distritos!$J$7:$J$66,1),Distritos!$J$7:$J$66,0))=0,"",INDEX(Distritos!$H$7:$H$66,MATCH(SMALL(Distritos!$J$7:$J$66,1),Distritos!$J$7:$J$66,0))),"")) -> Ate | C39: =IF($B$8=0,"",IFERROR(IF(INDEX(Distritos!$I$7:$I$66,MATCH(SMALL(Distritos!$J$7:$J$66,1),Distritos!$J$7:$J$66,0))=0,"",INDEX(Distritos!$I$7:$I$66,MATCH(SMALL(Distritos!$J$7:$J$66,1),Distritos!$J$7:$J$66,0))),"")) -> 25 | D39: =IF(OR($B$8=0,C39="",C39=0),"",C39/$B$8) -> 0.16339869 | E39: =IF(OR($B$8=0,B39=""),"",IFERROR(ROUND(IF($D$4="TODOS",IF($B$4="TODOS",(SUMIF('BD SECOS'!Q:Q,B39,'BD SECOS'!U:U)+SUMIF('BD PPA'!U:U,B39,'BD PPA'!AA:AA)+SUMIF('BD FRESCOS'!U:U,B39,'BD FRESCOS'!AA:AA))/(COUNTIF('BD SECOS'!Q:Q,B39)+COUNTIF('BD PPA'!U:U,B39)+COUNTIF('BD FRESCOS'!U:U,B39)),IF($B$4="SECOS",AVERAGEIF('BD SECOS'!Q:Q,B39,'BD SECOS'!U:U),IF($B$4="PPA",AVERAGEIF('BD PPA'!U:U,B39,'BD PPA'!AA:AA),AVERAGEIF('BD FRESCOS'!U:U,B39,'BD FRESCOS'!AA:AA)))),IF($B$4="TODOS",(SUMIFS('BD SECOS'!U:U,'BD SECOS'!Q:Q,B39,'BD SECOS'!AE:AE,$D$4)+SUMIFS('BD PPA'!AA:AA,'BD PPA'!U:U,B39,'BD PPA'!AK:AK,$D$4)+SUMIFS('BD FRESCOS'!AA:AA,'BD FRESCOS'!U:U,B39,'BD FRESCOS'!AK:AK,$D$4))/(COUNTIFS('BD SECOS'!Q:Q,B39,'BD SECOS'!AE:AE,$D$4)+COUNTIFS('BD PPA'!U:U,B39,'BD PPA'!AK:AK,$D$4)+COUNTIFS('BD FRESCOS'!U:U,B39,'BD FRESCOS'!AK:AK,$D$4)),IF($B$4="SECOS",AVERAGEIFS('BD SECOS'!U:U,'BD SECOS'!Q:Q,B39,'BD SECOS'!AE:AE,$D$4),IF($B$4="PPA",AVERAGEIFS('BD PPA'!AA:AA,'BD PPA'!U:U,B39,'BD PPA'!AK:AK,$D$4),AVERAGEIFS('BD FRESCOS'!AA:AA,'BD FRESCOS'!U:U,B39,'BD FRESCOS'!AK:AK,$D$4))))),2),"")) -> 7.82 | F39: =IF(OR($B$8=0,E39=""),"",IF(E39<=5,"🟢 Muy Cerca",IF(E39<=10,"🟡 Cerca",IF(E39<=20,"🟠 Moderada","🔴 Lejos")))) -> 🟡 Cerca | G39: =IF(OR($B$8=0,B39=""),"",IFERROR(ROUND(IF($D$4="TODOS",IF($B$4="TODOS",(SUMIF('BD SECOS'!Q:Q,B39,'BD SECOS'!Y:Y)+SUMIF('BD PPA'!U:U,B39,'BD PPA'!AE:AE)+SUMIF('BD FRESCOS'!U:U,B39,'BD FRESCOS'!AE:AE))/(COUNTIF('BD SECOS'!Q:Q,B39)+COUNTIF('BD PPA'!U:U,B39)+COUNTIF('BD FRESCOS'!U:U,B39)),IF($B$4="SECOS",AVERAGEIF('BD SECOS'!Q:Q,B39,'BD SECOS'!Y:Y),IF($B$4="PPA",AVERAGEIF('BD PPA'!U:U,B39,'BD PPA'!AE:AE),AVERAGEIF('BD FRESCOS'!U:U,B39,'BD FRESCOS'!AE:AE)))),IF($B$4="TODOS",(SUMIFS('BD SECOS'!Y:Y,'BD SECOS'!Q:Q,B39,'BD SECOS'!AE:AE,$D$4)+SUMIFS('BD PPA'!AE:AE,'BD PPA'!U:U,B39,'BD PPA'!AK:AK,$D$4)+SUMIFS('BD FRESCOS'!AE:AE,'BD FRESCOS'!U:U,B39,'BD FRESCOS'!AK:AK,$D$4))/(COUNTIFS('BD SECOS'!Q:Q,B39,'BD SECOS'!AE:AE,$D$4)+COUNTIFS('BD PPA'!U:U,B39,'BD PPA'!AK:AK,$D$4)+COUNTIFS('BD FRESCOS'!U:U,B39,'BD FRESCOS'!AK:AK,$D$4)),IF($B$4="SECOS",AVERAGEIFS('BD SECOS'!Y:Y,'BD SECOS'!Q:Q,B39,'BD SECOS'!AE:AE,$D$4),IF($B$4="PPA",AVERAGEIFS('BD PPA'!AE:AE,'BD PPA'!U:U,B39,'BD PPA'!AK:AK,$D$4),AVERAGEIFS('BD FRESCOS'!AE:AE,'BD FRESCOS'!U:U,B39,'BD FRESCOS'!AK:AK,$D$4))))),2),"")) -> 1.29 | H39: =IF(OR($B$8=0,G39=""),"",IF(G39<=1,"🟢 Muy Cerca",IF(G39<=3,"🟡 Cerca",IF(G39<=5,"🟠 Moderada","🔴 Lejos")))) -> 🟡 Cerca | I39: {=IF(OR($B$8=0,B39=""),"",IFERROR(IF($D$4="TODOS",IF($B$4="TODOS",INDEX('BD SECOS'!X:X,MATCH(B39,'BD SECOS'!Q:Q,0)),IF($B$4="SECOS",INDEX('BD SECOS'!X:X,MATCH(B39,'BD SECOS'!Q:Q,0)),IF($B$4="PPA",INDEX('BD PPA'!AD:AD,MATCH(B39,'BD PPA'!U:U,0)),INDEX('BD FRESCOS'!AD:AD,MATCH(B39,'BD FRESCOS'!U:U,0))))),IF($B$4="TODOS",IFERROR(INDEX('BD SECOS'!X:X,MATCH(1,('BD SECOS'!Q:Q=B39)*('BD SECOS'!AE:AE=$D$4),0)),IFERROR(INDEX('BD PPA'!AD:AD,MATCH(1,('BD PPA'!U:U=B39)*('BD PPA'!AK:AK=$D$4),0)),INDEX('BD FRESCOS'!AD:AD,MATCH(1,('BD FRESCOS'!U:U=B39)*('BD FRESCOS'!AK:AK=$D$4),0)))),IF($B$4="SECOS",INDEX('BD SECOS'!X:X,MATCH(1,('BD SECOS'!Q:Q=B39)*('BD SECOS'!AE:AE=$D$4),0)),IF($B$4="PPA",INDEX('BD PPA'!AD:AD,MATCH(1,('BD PPA'!U:U=B39)*('BD PPA'!AK:AK=$D$4),0)),INDEX('BD FRESCOS'!AD:AD,MATCH(1,('BD FRESCOS'!U:U=B39)*('BD FRESCOS'!AK:AK=$D$4),0)))))),""))} -> RUTA 7 | J39: =IF(OR($B$8=0,B39=""),"",IF(AND(E39>20,G39>5),"⚠️ Muy lejos del CD y paraderos",IF(E39>20,"⚠️ Muy lejos del CD",IF(G39>5,"⚠️ Lejos de paraderos","📍 Normal")))) -> 📍 Normal
A40: =IF(OR($B$8=0,C40="",C40=0),"",2) -> 2 | B40: =IF($B$8=0,"",IFERROR(IF(INDEX(Distritos!$I$7:$I$66,MATCH(SMALL(Distritos!$J$7:$J$66,2),Distritos!$J$7:$J$66,0))=0,"",INDEX(Distritos!$H$7:$H$66,MATCH(SMALL(Distritos!$J$7:$J$66,2),Distritos!$J$7:$J$66,0))),"")) -> San Juan De Lurigancho | C40: =IF($B$8=0,"",IFERROR(IF(INDEX(Distritos!$I$7:$I$66,MATCH(SMALL(Distritos!$J$7:$J$66,2),Distritos!$J$7:$J$66,0))=0,"",INDEX(Distritos!$I$7:$I$66,MATCH(SMALL(Distritos!$J$7:$J$66,2),Distritos!$J$7:$J$66,0))),"")) -> 22 | D40: =IF(OR($B$8=0,C40="",C40=0),"",C40/$B$8) -> 0.14379085 | E40: =IF(OR($B$8=0,B40=""),"",IFERROR(ROUND(IF($D$4="TODOS",IF($B$4="TODOS",(SUMIF('BD SECOS'!Q:Q,B40,'BD SECOS'!U:U)+SUMIF('BD PPA'!U:U,B40,'BD PPA'!AA:AA)+SUMIF('BD FRESCOS'!U:U,B40,'BD FRESCOS'!AA:AA))/(COUNTIF('BD SECOS'!Q:Q,B40)+COUNTIF('BD PPA'!U:U,B40)+COUNTIF('BD FRESCOS'!U:U,B40)),IF($B$4="SECOS",AVERAGEIF('BD SECOS'!Q:Q,B40,'BD SECOS'!U:U),IF($B$4="PPA",AVERAGEIF('BD PPA'!U:U,B40,'BD PPA'!AA:AA),AVERAGEIF('BD FRESCOS'!U:U,B40,'BD FRESCOS'!AA:AA)))),IF($B$4="TODOS",(SUMIFS('BD SECOS'!U:U,'BD SECOS'!Q:Q,B40,'BD SECOS'!AE:AE,$D$4)+SUMIFS('BD PPA'!AA:AA,'BD PPA'!U:U,B40,'BD PPA'!AK:AK,$D$4)+SUMIFS('BD FRESCOS'!AA:AA,'BD FRESCOS'!U:U,B40,'BD FRESCOS'!AK:AK,$D$4))/(COUNTIFS('BD SECOS'!Q:Q,B40,'BD SECOS'!AE:AE,$D$4)+COUNTIFS('BD PPA'!U:U,B40,'BD PPA'!AK:AK,$D$4)+COUNTIFS('BD FRESCOS'!U:U,B40,'BD FRESCOS'!AK:AK,$D$4)),IF($B$4="SECOS",AVERAGEIFS('BD SECOS'!U:U,'BD SECOS'!Q:Q,B40,'BD SECOS'!AE:AE,$D$4),IF($B$4="PPA",AVERAGEIFS('BD PPA'!AA:AA,'BD PPA'!U:U,B40,'BD PPA'!AK:AK,$D$4),AVERAGEIFS('BD FRESCOS'!AA:AA,'BD FRESCOS'!U:U,B40,'BD FRESCOS'!AK:AK,$D$4))))),2),"")) -> 11.75 | F40: =IF(OR($B$8=0,E40=""),"",IF(E40<=5,"🟢 Muy Cerca",IF(E40<=10,"🟡 Cerca",IF(E40<=20,"🟠 Moderada","🔴 Lejos")))) -> 🟠 Moderada | G40: =IF(OR($B$8=0,B40=""),"",IFERROR(ROUND(IF($D$4="TODOS",IF($B$4="TODOS",(SUMIF('BD SECOS'!Q:Q,B40,'BD SECOS'!Y:Y)+SUMIF('BD PPA'!U:U,B40,'BD PPA'!AE:AE)+SUMIF('BD FRESCOS'!U:U,B40,'BD FRESCOS'!AE:AE))/(COUNTIF('BD SECOS'!Q:Q,B40)+COUNTIF('BD PPA'!U:U,B40)+COUNTIF('BD FRESCOS'!U:U,B40)),IF($B$4="SECOS",AVERAGEIF('BD SECOS'!Q:Q,B40,'BD SECOS'!Y:Y),IF($B$4="PPA",AVERAGEIF('BD PPA'!U:U,B40,'BD PPA'!AE:AE),AVERAGEIF('BD FRESCOS'!U:U,B40,'BD FRESCOS'!AE:AE)))),IF($B$4="TODOS",(SUMIFS('BD SECOS'!Y:Y,'BD SECOS'!Q:Q,B40,'BD SECOS'!AE:AE,$D$4)+SUMIFS('BD PPA'!AE:AE,'BD PPA'!U:U,B40,'BD PPA'!AK:AK,$D$4)+SUMIFS('BD FRESCOS'!AE:AE,'BD FRESCOS'!U:U,B40,'BD FRESCOS'!AK:AK,$D$4))/(COUNTIFS('BD SECOS'!Q:Q,B40,'BD SECOS'!AE:AE,$D$4)+COUNTIFS('BD PPA'!U:U,B40,'BD PPA'!AK:AK,$D$4)+COUNTIFS('BD FRESCOS'!U:U,B40,'BD FRESCOS'!AK:AK,$D$4)),IF($B$4="SECOS",AVERAGEIFS('BD SECOS'!Y:Y,'BD SECOS'!Q:Q,B40,'BD SECOS'!AE:AE,$D$4),IF($B$4="PPA",AVERAGEIFS('BD PPA'!AE:AE,'BD PPA'!U:U,B40,'BD PPA'!AK:AK,$D$4),AVERAGEIFS('BD FRESCOS'!AE:AE,'BD FRESCOS'!U:U,B40,'BD FRESCOS'!AK:AK,$D$4))))),2),"")) -> 1.78 | H40: =IF(OR($B$8=0,G40=""),"",IF(G40<=1,"🟢 Muy Cerca",IF(G40<=3,"🟡 Cerca",IF(G40<=5,"🟠 Moderada","🔴 Lejos")))) -> 🟡 Cerca | I40: {=IF(OR($B$8=0,B40=""),"",IFERROR(IF($D$4="TODOS",IF($B$4="TODOS",INDEX('BD SECOS'!X:X,MATCH(B40,'BD SECOS'!Q:Q,0)),IF($B$4="SECOS",INDEX('BD SECOS'!X:X,MATCH(B40,'BD SECOS'!Q:Q,0)),IF($B$4="PPA",INDEX('BD PPA'!AD:AD,MATCH(B40,'BD PPA'!U:U,0)),INDEX('BD FRESCOS'!AD:AD,MATCH(B40,'BD FRESCOS'!U:U,0))))),IF($B$4="TODOS",IFERROR(INDEX('BD SECOS'!X:X,MATCH(1,('BD SECOS'!Q:Q=B40)*('BD SECOS'!AE:AE=$D$4),0)),IFERROR(INDEX('BD PPA'!AD:AD,MATCH(1,('BD PPA'!U:U=B40)*('BD PPA'!AK:AK=$D$4),0)),INDEX('BD FRESCOS'!AD:AD,MATCH(1,('BD FRESCOS'!U:U=B40)*('BD FRESCOS'!AK:AK=$D$4),0)))),IF($B$4="SECOS",INDEX('BD SECOS'!X:X,MATCH(1,('BD SECOS'!Q:Q=B40)*('BD SECOS'!AE:AE=$D$4),0)),IF($B$4="PPA",INDEX('BD PPA'!AD:AD,MATCH(1,('BD PPA'!U:U=B40)*('BD PPA'!AK:AK=$D$4),0)),INDEX('BD FRESCOS'!AD:AD,MATCH(1,('BD FRESCOS'!U:U=B40)*('BD FRESCOS'!AK:AK=$D$4),0)))))),""))} -> RUTA 8 | J40: =IF(OR($B$8=0,B40=""),"",IF(AND(E40>20,G40>5),"⚠️ Muy lejos del CD y paraderos",IF(E40>20,"⚠️ Muy lejos del CD",IF(G40>5,"⚠️ Lejos de paraderos","📍 Normal")))) -> 📍 Normal
A41: =IF(OR($B$8=0,C41="",C41=0),"",3) -> 3 | B41: =IF($B$8=0,"",IFERROR(IF(INDEX(Distritos!$I$7:$I$66,MATCH(SMALL(Distritos!$J$7:$J$66,3),Distritos!$J$7:$J$66,0))=0,"",INDEX(Distritos!$H$7:$H$66,MATCH(SMALL(Distritos!$J$7:$J$66,3),Distritos!$J$7:$J$66,0))),"")) -> Lurigancho | C41: =IF($B$8=0,"",IFERROR(IF(INDEX(Distritos!$I$7:$I$66,MATCH(SMALL(Distritos!$J$7:$J$66,3),Distritos!$J$7:$J$66,0))=0,"",INDEX(Distritos!$I$7:$I$66,MATCH(SMALL(Distritos!$J$7:$J$66,3),Distritos!$J$7:$J$66,0))),"")) -> 21 | D41: =IF(OR($B$8=0,C41="",C41=0),"",C41/$B$8) -> 0.1372549 | E41: =IF(OR($B$8=0,B41=""),"",IFERROR(ROUND(IF($D$4="TODOS",IF($B$4="TODOS",(SUMIF('BD SECOS'!Q:Q,B41,'BD SECOS'!U:U)+SUMIF('BD PPA'!U:U,B41,'BD PPA'!AA:AA)+SUMIF('BD FRESCOS'!U:U,B41,'BD FRESCOS'!AA:AA))/(COUNTIF('BD SECOS'!Q:Q,B41)+COUNTIF('BD PPA'!U:U,B41)+COUNTIF('BD FRESCOS'!U:U,B41)),IF($B$4="SECOS",AVERAGEIF('BD SECOS'!Q:Q,B41,'BD SECOS'!U:U),IF($B$4="PPA",AVERAGEIF('BD PPA'!U:U,B41,'BD PPA'!AA:AA),AVERAGEIF('BD FRESCOS'!U:U,B41,'BD FRESCOS'!AA:AA)))),IF($B$4="TODOS",(SUMIFS('BD SECOS'!U:U,'BD SECOS'!Q:Q,B41,'BD SECOS'!AE:AE,$D$4)+SUMIFS('BD PPA'!AA:AA,'BD PPA'!U:U,B41,'BD PPA'!AK:AK,$D$4)+SUMIFS('BD FRESCOS'!AA:AA,'BD FRESCOS'!U:U,B41,'BD FRESCOS'!AK:AK,$D$4))/(COUNTIFS('BD SECOS'!Q:Q,B41,'BD SECOS'!AE:AE,$D$4)+COUNTIFS('BD PPA'!U:U,B41,'BD PPA'!AK:AK,$D$4)+COUNTIFS('BD FRESCOS'!U:U,B41,'BD FRESCOS'!AK:AK,$D$4)),IF($B$4="SECOS",AVERAGEIFS('BD SECOS'!U:U,'BD SECOS'!Q:Q,B41,'BD SECOS'!AE:AE,$D$4),IF($B$4="PPA",AVERAGEIFS('BD PPA'!AA:AA,'BD PPA'!U:U,B41,'BD PPA'!AK:AK,$D$4),AVERAGEIFS('BD FRESCOS'!AA:AA,'BD FRESCOS'!U:U,B41,'BD FRESCOS'!AK:AK,$D$4))))),2),"")) -> 9.71 | F41: =IF(OR($B$8=0,E41=""),"",IF(E41<=5,"🟢 Muy Cerca",IF(E41<=10,"🟡 Cerca",IF(E41<=20,"🟠 Moderada","🔴 Lejos")))) -> 🟡 Cerca | G41: =IF(OR($B$8=0,B41=""),"",IFERROR(ROUND(IF($D$4="TODOS",IF($B$4="TODOS",(SUMIF('BD SECOS'!Q:Q,B41,'BD SECOS'!Y:Y)+SUMIF('BD PPA'!U:U,B41,'BD PPA'!AE:AE)+SUMIF('BD FRESCOS'!U:U,B41,'BD FRESCOS'!AE:AE))/(COUNTIF('BD SECOS'!Q:Q,B41)+COUNTIF('BD PPA'!U:U,B41)+COUNTIF('BD FRESCOS'!U:U,B41)),IF($B$4="SECOS",AVERAGEIF('BD SECOS'!Q:Q,B41,'BD SECOS'!Y:Y),IF($B$4="PPA",AVERAGEIF('BD PPA'!U:U,B41,'BD PPA'!AE:AE),AVERAGEIF('BD FRESCOS'!U:U,B41,'BD FRESCOS'!AE:AE)))),IF($B$4="TODOS",(SUMIFS('BD SECOS'!Y:Y,'BD SECOS'!Q:Q,B41,'BD SECOS'!AE:AE,$D$4)+SUMIFS('BD PPA'!AE:AE,'BD PPA'!U:U,B41,'BD PPA'!AK:AK,$D$4)+SUMIFS('BD FRESCOS'!AE:AE,'BD FRESCOS'!U:U,B41,'BD FRESCOS'!AK:AK,$D$4))/(COUNTIFS('BD SECOS'!Q:Q,B41,'BD SECOS'!AE:AE,$D$4)+COUNTIFS('BD PPA'!U:U,B41,'BD PPA'!AK:AK,$D$4)+COUNTIFS('BD FRESCOS'!U:U,B41,'BD FRESCOS'!AK:AK,$D$4)),IF($B$4="SECOS",AVERAGEIFS('BD SECOS'!Y:Y,'BD SECOS'!Q:Q,B41,'BD SECOS'!AE:AE,$D$4),IF($B$4="PPA",AVERAGEIFS('BD PPA'!AE:AE,'BD PPA'!U:U,B41,'BD PPA'!AK:AK,$D$4),AVERAGEIFS('BD FRESCOS'!AE:AE,'BD FRESCOS'!U:U,B41,'BD FRESCOS'!AK:AK,$D$4))))),2),"")) -> 3.41 | H41: =IF(OR($B$8=0,G41=""),"",IF(G41<=1,"🟢 Muy Cerca",IF(G41<=3,"🟡 Cerca",IF(G41<=5,"🟠 Moderada","🔴 Lejos")))) -> 🟠 Moderada | I41: {=IF(OR($B$8=0,B41=""),"",IFERROR(IF($D$4="TODOS",IF($B$4="TODOS",INDEX('BD SECOS'!X:X,MATCH(B41,'BD SECOS'!Q:Q,0)),IF($B$4="SECOS",INDEX('BD SECOS'!X:X,MATCH(B41,'BD SECOS'!Q:Q,0)),IF($B$4="PPA",INDEX('BD PPA'!AD:AD,MATCH(B41,'BD PPA'!U:U,0)),INDEX('BD FRESCOS'!AD:AD,MATCH(B41,'BD FRESCOS'!U:U,0))))),IF($B$4="TODOS",IFERROR(INDEX('BD SECOS'!X:X,MATCH(1,('BD SECOS'!Q:Q=B41)*('BD SECOS'!AE:AE=$D$4),0)),IFERROR(INDEX('BD PPA'!AD:AD,MATCH(1,('BD PPA'!U:U=B41)*('BD PPA'!AK:AK=$D$4),0)),INDEX('BD FRESCOS'!AD:AD,MATCH(1,('BD FRESCOS'!U:U=B41)*('BD FRESCOS'!AK:AK=$D$4),0)))),IF($B$4="SECOS",INDEX('BD SECOS'!X:X,MATCH(1,('BD SECOS'!Q:Q=B41)*('BD SECOS'!AE:AE=$D$4),0)),IF($B$4="PPA",INDEX('BD PPA'!AD:AD,MATCH(1,('BD PPA'!U:U=B41)*('BD PPA'!AK:AK=$D$4),0)),INDEX('BD FRESCOS'!AD:AD,MATCH(1,('BD FRESCOS'!U:U=B41)*('BD FRESCOS'!AK:AK=$D$4),0)))))),""))} -> RUTA 2 | J41: =IF(OR($B$8=0,B41=""),"",IF(AND(E41>20,G41>5),"⚠️ Muy lejos del CD y paraderos",IF(E41>20,"⚠️ Muy lejos del CD",IF(G41>5,"⚠️ Lejos de paraderos","📍 Normal")))) -> 📍 Normal
A42: =IF(OR($B$8=0,C42="",C42=0),"",4) -> 4 | B42: =IF($B$8=0,"",IFERROR(IF(INDEX(Distritos!$I$7:$I$66,MATCH(SMALL(Distritos!$J$7:$J$66,4),Distritos!$J$7:$J$66,0))=0,"",INDEX(Distritos!$H$7:$H$66,MATCH(SMALL(Distritos!$J$7:$J$66,4),Distritos!$J$7:$J$66,0))),"")) -> Lima | C42: =IF($B$8=0,"",IFERROR(IF(INDEX(Distritos!$I$7:$I$66,MATCH(SMALL(Distritos!$J$7:$J$66,4),Distritos!$J$7:$J$66,0))=0,"",INDEX(Distritos!$I$7:$I$66,MATCH(SMALL(Distritos!$J$7:$J$66,4),Distritos!$J$7:$J$66,0))),"")) -> 10 | D42: =IF(OR($B$8=0,C42="",C42=0),"",C42/$B$8) -> 0.065359477 | E42: =IF(OR($B$8=0,B42=""),"",IFERROR(ROUND(IF($D$4="TODOS",IF($B$4="TODOS",(SUMIF('BD SECOS'!Q:Q,B42,'BD SECOS'!U:U)+SUMIF('BD PPA'!U:U,B42,'BD PPA'!AA:AA)+SUMIF('BD FRESCOS'!U:U,B42,'BD FRESCOS'!AA:AA))/(COUNTIF('BD SECOS'!Q:Q,B42)+COUNTIF('BD PPA'!U:U,B42)+COUNTIF('BD FRESCOS'!U:U,B42)),IF($B$4="SECOS",AVERAGEIF('BD SECOS'!Q:Q,B42,'BD SECOS'!U:U),IF($B$4="PPA",AVERAGEIF('BD PPA'!U:U,B42,'BD PPA'!AA:AA),AVERAGEIF('BD FRESCOS'!U:U,B42,'BD FRESCOS'!AA:AA)))),IF($B$4="TODOS",(SUMIFS('BD SECOS'!U:U,'BD SECOS'!Q:Q,B42,'BD SECOS'!AE:AE,$D$4)+SUMIFS('BD PPA'!AA:AA,'BD PPA'!U:U,B42,'BD PPA'!AK:AK,$D$4)+SUMIFS('BD FRESCOS'!AA:AA,'BD FRESCOS'!U:U,B42,'BD FRESCOS'!AK:AK,$D$4))/(COUNTIFS('BD SECOS'!Q:Q,B42,'BD SECOS'!AE:AE,$D$4)+COUNTIFS('BD PPA'!U:U,B42,'BD PPA'!AK:AK,$D$4)+COUNTIFS('BD FRESCOS'!U:U,B42,'BD FRESCOS'!AK:AK,$D$4)),IF($B$4="SECOS",AVERAGEIFS('BD SECOS'!U:U,'BD SECOS'!Q:Q,B42,'BD SECOS'!AE:AE,$D$4),IF($B$4="PPA",AVERAGEIFS('BD PPA'!AA:AA,'BD PPA'!U:U,B42,'BD PPA'!AK:AK,$D$4),AVERAGEIFS('BD FRESCOS'!AA:AA,'BD FRESCOS'!U:U,B42,'BD FRESCOS'!AK:AK,$D$4))))),2),"")) -> 16.92 | F42: =IF(OR($B$8=0,E42=""),"",IF(E42<=5,"🟢 Muy Cerca",IF(E42<=10,"🟡 Cerca",IF(E42<=20,"🟠 Moderada","🔴 Lejos")))) -> 🟠 Moderada | G42: =IF(OR($B$8=0,B42=""),"",IFERROR(ROUND(IF($D$4="TODOS",IF($B$4="TODOS",(SUMIF('BD SECOS'!Q:Q,B42,'BD SECOS'!Y:Y)+SUMIF('BD PPA'!U:U,B42,'BD PPA'!AE:AE)+SUMIF('BD FRESCOS'!U:U,B42,'BD FRESCOS'!AE:AE))/(COUNTIF('BD SECOS'!Q:Q,B42)+COUNTIF('BD PPA'!U:U,B42)+COUNTIF('BD FRESCOS'!U:U,B42)),IF($B$4="SECOS",AVERAGEIF('BD SECOS'!Q:Q,B42,'BD SECOS'!Y:Y),IF($B$4="PPA",AVERAGEIF('BD PPA'!U:U,B42,'BD PPA'!AE:AE),AVERAGEIF('BD FRESCOS'!U:U,B42,'BD FRESCOS'!AE:AE)))),IF($B$4="TODOS",(SUMIFS('BD SECOS'!Y:Y,'BD SECOS'!Q:Q,B42,'BD SECOS'!AE:AE,$D$4)+SUMIFS('BD PPA'!AE:AE,'BD PPA'!U:U,B42,'BD PPA'!AK:AK,$D$4)+SUMIFS('BD FRESCOS'!AE:AE,'BD FRESCOS'!U:U,B42,'BD FRESCOS'!AK:AK,$D$4))/(COUNTIFS('BD SECOS'!Q:Q,B42,'BD SECOS'!AE:AE,$D$4)+COUNTIFS('BD PPA'!U:U,B42,'BD PPA'!AK:AK,$D$4)+COUNTIFS('BD FRESCOS'!U:U,B42,'BD FRESCOS'!AK:AK,$D$4)),IF($B$4="SECOS",AVERAGEIFS('BD SECOS'!Y:Y,'BD SECOS'!Q:Q,B42,'BD SECOS'!AE:AE,$D$4),IF($B$4="PPA",AVERAGEIFS('BD PPA'!AE:AE,'BD PPA'!U:U,B42,'BD PPA'!AK:AK,$D$4),AVERAGEIFS('BD FRESCOS'!AE:AE,'BD FRESCOS'!U:U,B42,'BD FRESCOS'!AK:AK,$D$4))))),2),"")) -> 1.37 | H42: =IF(OR($B$8=0,G42=""),"",IF(G42<=1,"🟢 Muy Cerca",IF(G42<=3,"🟡 Cerca",IF(G42<=5,"🟠 Moderada","🔴 Lejos")))) -> 🟡 Cerca | I42: {=IF(OR($B$8=0,B42=""),"",IFERROR(IF($D$4="TODOS",IF($B$4="TODOS",INDEX('BD SECOS'!X:X,MATCH(B42,'BD SECOS'!Q:Q,0)),IF($B$4="SECOS",INDEX('BD SECOS'!X:X,MATCH(B42,'BD SECOS'!Q:Q,0)),IF($B$4="PPA",INDEX('BD PPA'!AD:AD,MATCH(B42,'BD PPA'!U:U,0)),INDEX('BD FRESCOS'!AD:AD,MATCH(B42,'BD FRESCOS'!U:U,0))))),IF($B$4="TODOS",IFERROR(INDEX('BD SECOS'!X:X,MATCH(1,('BD SECOS'!Q:Q=B42)*('BD SECOS'!AE:AE=$D$4),0)),IFERROR(INDEX('BD PPA'!AD:AD,MATCH(1,('BD PPA'!U:U=B42)*('BD PPA'!AK:AK=$D$4),0)),INDEX('BD FRESCOS'!AD:AD,MATCH(1,('BD FRESCOS'!U:U=B42)*('BD FRESCOS'!AK:AK=$D$4),0)))),IF($B$4="SECOS",INDEX('BD SECOS'!X:X,MATCH(1,('BD SECOS'!Q:Q=B42)*('BD SECOS'!AE:AE=$D$4),0)),IF($B$4="PPA",INDEX('BD PPA'!AD:AD,MATCH(1,('BD PPA'!U:U=B42)*('BD PPA'!AK:AK=$D$4),0)),INDEX('BD FRESCOS'!AD:AD,MATCH(1,('BD FRESCOS'!U:U=B42)*('BD FRESCOS'!AK:AK=$D$4),0)))))),""))} -> RUTA 9 | J42: =IF(OR($B$8=0,B42=""),"",IF(AND(E42>20,G42>5),"⚠️ Muy lejos del CD y paraderos",IF(E42>20,"⚠️ Muy lejos del CD",IF(G42>5,"⚠️ Lejos de paraderos","📍 Normal")))) -> 📍 Normal
A43: =IF(OR($B$8=0,C43="",C43=0),"",5) -> 5 | B43: =IF($B$8=0,"",IFERROR(IF(INDEX(Distritos!$I$7:$I$66,MATCH(SMALL(Distritos!$J$7:$J$66,5),Distritos!$J$7:$J$66,0))=0,"",INDEX(Distritos!$H$7:$H$66,MATCH(SMALL(Distritos!$J$7:$J$66,5),Distritos!$J$7:$J$66,0))),"")) -> Santiago De Surco | C43: =IF($B$8=0,"",IFERROR(IF(INDEX(Distritos!$I$7:$I$66,MATCH(SMALL(Distritos!$J$7:$J$66,5),Distritos!$J$7:$J$66,0))=0,"",INDEX(Distritos!$I$7:$I$66,MATCH(SMALL(Distritos!$J$7:$J$66,5),Distritos!$J$7:$J$66,0))),"")) -> 7 | D43: =IF(OR($B$8=0,C43="",C43=0),"",C43/$B$8) -> 0.045751634 | E43: =IF(OR($B$8=0,B43=""),"",IFERROR(ROUND(IF($D$4="TODOS",IF($B$4="TODOS",(SUMIF('BD SECOS'!Q:Q,B43,'BD SECOS'!U:U)+SUMIF('BD PPA'!U:U,B43,'BD PPA'!AA:AA)+SUMIF('BD FRESCOS'!U:U,B43,'BD FRESCOS'!AA:AA))/(COUNTIF('BD SECOS'!Q:Q,B43)+COUNTIF('BD PPA'!U:U,B43)+COUNTIF('BD FRESCOS'!U:U,B43)),IF($B$4="SECOS",AVERAGEIF('BD SECOS'!Q:Q,B43,'BD SECOS'!U:U),IF($B$4="PPA",AVERAGEIF('BD PPA'!U:U,B43,'BD PPA'!AA:AA),AVERAGEIF('BD FRESCOS'!U:U,B43,'BD FRESCOS'!AA:AA)))),IF($B$4="TODOS",(SUMIFS('BD SECOS'!U:U,'BD SECOS'!Q:Q,B43,'BD SECOS'!AE:AE,$D$4)+SUMIFS('BD PPA'!AA:AA,'BD PPA'!U:U,B43,'BD PPA'!AK:AK,$D$4)+SUMIFS('BD FRESCOS'!AA:AA,'BD FRESCOS'!U:U,B43,'BD FRESCOS'!AK:AK,$D$4))/(COUNTIFS('BD SECOS'!Q:Q,B43,'BD SECOS'!AE:AE,$D$4)+COUNTIFS('BD PPA'!U:U,B43,'BD PPA'!AK:AK,$D$4)+COUNTIFS('BD FRESCOS'!U:U,B43,'BD FRESCOS'!AK:AK,$D$4)),IF($B$4="SECOS",AVERAGEIFS('BD SECOS'!U:U,'BD SECOS'!Q:Q,B43,'BD SECOS'!AE:AE,$D$4),IF($B$4="PPA",AVERAGEIFS('BD PPA'!AA:AA,'BD PPA'!U:U,B43,'BD PPA'!AK:AK,$D$4),AVERAGEIFS('BD FRESCOS'!AA:AA,'BD FRESCOS'!U:U,B43,'BD FRESCOS'!AK:AK,$D$4))))),2),"")) -> 18.72 | F43: =IF(OR($B$8=0,E43=""),"",IF(E43<=5,"🟢 Muy Cerca",IF(E43<=10,"🟡 Cerca",IF(E43<=20,"🟠 Moderada","🔴 Lejos")))) -> 🟠 Moderada | G43: =IF(OR($B$8=0,B43=""),"",IFERROR(ROUND(IF($D$4="TODOS",IF($B$4="TODOS",(SUMIF('BD SECOS'!Q:Q,B43,'BD SECOS'!Y:Y)+SUMIF('BD PPA'!U:U,B43,'BD PPA'!AE:AE)+SUMIF('BD FRESCOS'!U:U,B43,'BD FRESCOS'!AE:AE))/(COUNTIF('BD SECOS'!Q:Q,B43)+COUNTIF('BD PPA'!U:U,B43)+COUNTIF('BD FRESCOS'!U:U,B43)),IF($B$4="SECOS",AVERAGEIF('BD SECOS'!Q:Q,B43,'BD SECOS'!Y:Y),IF($B$4="PPA",AVERAGEIF('BD PPA'!U:U,B43,'BD PPA'!AE:AE),AVERAGEIF('BD FRESCOS'!U:U,B43,'BD FRESCOS'!AE:AE)))),IF($B$4="TODOS",(SUMIFS('BD SECOS'!Y:Y,'BD SECOS'!Q:Q,B43,'BD SECOS'!AE:AE,$D$4)+SUMIFS('BD PPA'!AE:AE,'BD PPA'!U:U,B43,'BD PPA'!AK:AK,$D$4)+SUMIFS('BD FRESCOS'!AE:AE,'BD FRESCOS'!U:U,B43,'BD FRESCOS'!AK:AK,$D$4))/(COUNTIFS('BD SECOS'!Q:Q,B43,'BD SECOS'!AE:AE,$D$4)+COUNTIFS('BD PPA'!U:U,B43,'BD PPA'!AK:AK,$D$4)+COUNTIFS('BD FRESCOS'!U:U,B43,'BD FRESCOS'!AK:AK,$D$4)),IF($B$4="SECOS",AVERAGEIFS('BD SECOS'!Y:Y,'BD SECOS'!Q:Q,B43,'BD SECOS'!AE:AE,$D$4),IF($B$4="PPA",AVERAGEIFS('BD PPA'!AE:AE,'BD PPA'!U:U,B43,'BD PPA'!AK:AK,$D$4),AVERAGEIFS('BD FRESCOS'!AE:AE,'BD FRESCOS'!U:U,B43,'BD FRESCOS'!AK:AK,$D$4))))),2),"")) -> 1.29 | H43: =IF(OR($B$8=0,G43=""),"",IF(G43<=1,"🟢 Muy Cerca",IF(G43<=3,"🟡 Cerca",IF(G43<=5,"🟠 Moderada","🔴 Lejos")))) -> 🟡 Cerca | I43: {=IF(OR($B$8=0,B43=""),"",IFERROR(IF($D$4="TODOS",IF($B$4="TODOS",INDEX('BD SECOS'!X:X,MATCH(B43,'BD SECOS'!Q:Q,0)),IF($B$4="SECOS",INDEX('BD SECOS'!X:X,MATCH(B43,'BD SECOS'!Q:Q,0)),IF($B$4="PPA",INDEX('BD PPA'!AD:AD,MATCH(B43,'BD PPA'!U:U,0)),INDEX('BD FRESCOS'!AD:AD,MATCH(B43,'BD FRESCOS'!U:U,0))))),IF($B$4="TODOS",IFERROR(INDEX('BD SECOS'!X:X,MATCH(1,('BD SECOS'!Q:Q=B43)*('BD SECOS'!AE:AE=$D$4),0)),IFERROR(INDEX('BD PPA'!AD:AD,MATCH(1,('BD PPA'!U:U=B43)*('BD PPA'!AK:AK=$D$4),0)),INDEX('BD FRESCOS'!AD:AD,MATCH(1,('BD FRESCOS'!U:U=B43)*('BD FRESCOS'!AK:AK=$D$4),0)))),IF($B$4="SECOS",INDEX('BD SECOS'!X:X,MATCH(1,('BD SECOS'!Q:Q=B43)*('BD SECOS'!AE:AE=$D$4),0)),IF($B$4="PPA",INDEX('BD PPA'!AD:AD,MATCH(1,('BD PPA'!U:U=B43)*('BD PPA'!AK:AK=$D$4),0)),INDEX('BD FRESCOS'!AD:AD,MATCH(1,('BD FRESCOS'!U:U=B43)*('BD FRESCOS'!AK:AK=$D$4),0)))))),""))} -> RUTA 7 | J43: =IF(OR($B$8=0,B43=""),"",IF(AND(E43>20,G43>5),"⚠️ Muy lejos del CD y paraderos",IF(E43>20,"⚠️ Muy lejos del CD",IF(G43>5,"⚠️ Lejos de paraderos","📍 Normal")))) -> 📍 Normal
A44: =IF(OR($B$8=0,C44="",C44=0),"",6) -> 6 | B44: =IF($B$8=0,"",IFERROR(IF(INDEX(Distritos!$I$7:$I$66,MATCH(SMALL(Distritos!$J$7:$J$66,6),Distritos!$J$7:$J$66,0))=0,"",INDEX(Distritos!$H$7:$H$66,MATCH(SMALL(Distritos!$J$7:$J$66,6),Distritos!$J$7:$J$66,0))),"")) -> Callao | C44: =IF($B$8=0,"",IFERROR(IF(INDEX(Distritos!$I$7:$I$66,MATCH(SMALL(Distritos!$J$7:$J$66,6),Distritos!$J$7:$J$66,0))=0,"",INDEX(Distritos!$I$7:$I$66,MATCH(SMALL(Distritos!$J$7:$J$66,6),Distritos!$J$7:$J$66,0))),"")) -> 6 | D44: =IF(OR($B$8=0,C44="",C44=0),"",C44/$B$8) -> 0.039215686 | E44: =IF(OR($B$8=0,B44=""),"",IFERROR(ROUND(IF($D$4="TODOS",IF($B$4="TODOS",(SUMIF('BD SECOS'!Q:Q,B44,'BD SECOS'!U:U)+SUMIF('BD PPA'!U:U,B44,'BD PPA'!AA:AA)+SUMIF('BD FRESCOS'!U:U,B44,'BD FRESCOS'!AA:AA))/(COUNTIF('BD SECOS'!Q:Q,B44)+COUNTIF('BD PPA'!U:U,B44)+COUNTIF('BD FRESCOS'!U:U,B44)),IF($B$4="SECOS",AVERAGEIF('BD SECOS'!Q:Q,B44,'BD SECOS'!U:U),IF($B$4="PPA",AVERAGEIF('BD PPA'!U:U,B44,'BD PPA'!AA:AA),AVERAGEIF('BD FRESCOS'!U:U,B44,'BD FRESCOS'!AA:AA)))),IF($B$4="TODOS",(SUMIFS('BD SECOS'!U:U,'BD SECOS'!Q:Q,B44,'BD SECOS'!AE:AE,$D$4)+SUMIFS('BD PPA'!AA:AA,'BD PPA'!U:U,B44,'BD PPA'!AK:AK,$D$4)+SUMIFS('BD FRESCOS'!AA:AA,'BD FRESCOS'!U:U,B44,'BD FRESCOS'!AK:AK,$D$4))/(COUNTIFS('BD SECOS'!Q:Q,B44,'BD SECOS'!AE:AE,$D$4)+COUNTIFS('BD PPA'!U:U,B44,'BD PPA'!AK:AK,$D$4)+COUNTIFS('BD FRESCOS'!U:U,B44,'BD FRESCOS'!AK:AK,$D$4)),IF($B$4="SECOS",AVERAGEIFS('BD SECOS'!U:U,'BD SECOS'!Q:Q,B44,'BD SECOS'!AE:AE,$D$4),IF($B$4="PPA",AVERAGEIFS('BD PPA'!AA:AA,'BD PPA'!U:U,B44,'BD PPA'!AK:AK,$D$4),AVERAGEIFS('BD FRESCOS'!AA:AA,'BD FRESCOS'!U:U,B44,'BD FRESCOS'!AK:AK,$D$4))))),2),"")) -> 23.02 | F44: =IF(OR($B$8=0,E44=""),"",IF(E44<=5,"🟢 Muy Cerca",IF(E44<=10,"🟡 Cerca",IF(E44<=20,"🟠 Moderada","🔴 Lejos")))) -> 🔴 Lejos | G44: =IF(OR($B$8=0,B44=""),"",IFERROR(ROUND(IF($D$4="TODOS",IF($B$4="TODOS",(SUMIF('BD SECOS'!Q:Q,B44,'BD SECOS'!Y:Y)+SUMIF('BD PPA'!U:U,B44,'BD PPA'!AE:AE)+SUMIF('BD FRESCOS'!U:U,B44,'BD FRESCOS'!AE:AE))/(COUNTIF('BD SECOS'!Q:Q,B44)+COUNTIF('BD PPA'!U:U,B44)+COUNTIF('BD FRESCOS'!U:U,B44)),IF($B$4="SECOS",AVERAGEIF('BD SECOS'!Q:Q,B44,'BD SECOS'!Y:Y),IF($B$4="PPA",AVERAGEIF('BD PPA'!U:U,B44,'BD PPA'!AE:AE),AVERAGEIF('BD FRESCOS'!U:U,B44,'BD FRESCOS'!AE:AE)))),IF($B$4="TODOS",(SUMIFS('BD SECOS'!Y:Y,'BD SECOS'!Q:Q,B44,'BD SECOS'!AE:AE,$D$4)+SUMIFS('BD PPA'!AE:AE,'BD PPA'!U:U,B44,'BD PPA'!AK:AK,$D$4)+SUMIFS('BD FRESCOS'!AE:AE,'BD FRESCOS'!U:U,B44,'BD FRESCOS'!AK:AK,$D$4))/(COUNTIFS('BD SECOS'!Q:Q,B44,'BD SECOS'!AE:AE,$D$4)+COUNTIFS('BD PPA'!U:U,B44,'BD PPA'!AK:AK,$D$4)+COUNTIFS('BD FRESCOS'!U:U,B44,'BD FRESCOS'!AK:AK,$D$4)),IF($B$4="SECOS",AVERAGEIFS('BD SECOS'!Y:Y,'BD SECOS'!Q:Q,B44,'BD SECOS'!AE:AE,$D$4),IF($B$4="PPA",AVERAGEIFS('BD PPA'!AE:AE,'BD PPA'!U:U,B44,'BD PPA'!AK:AK,$D$4),AVERAGEIFS('BD FRESCOS'!AE:AE,'BD FRESCOS'!U:U,B44,'BD FRESCOS'!AK:AK,$D$4))))),2),"")) -> 1.53 | H44: =IF(OR($B$8=0,G44=""),"",IF(G44<=1,"🟢 Muy Cerca",IF(G44<=3,"🟡 Cerca",IF(G44<=5,"🟠 Moderada","🔴 Lejos")))) -> 🟡 Cerca | I44: {=IF(OR($B$8=0,B44=""),"",IFERROR(IF($D$4="TODOS",IF($B$4="TODOS",INDEX('BD SECOS'!X:X,MATCH(B44,'BD SECOS'!Q:Q,0)),IF($B$4="SECOS",INDEX('BD SECOS'!X:X,MATCH(B44,'BD SECOS'!Q:Q,0)),IF($B$4="PPA",INDEX('BD PPA'!AD:AD,MATCH(B44,'BD PPA'!U:U,0)),INDEX('BD FRESCOS'!AD:AD,MATCH(B44,'BD FRESCOS'!U:U,0))))),IF($B$4="TODOS",IFERROR(INDEX('BD SECOS'!X:X,MATCH(1,('BD SECOS'!Q:Q=B44)*('BD SECOS'!AE:AE=$D$4),0)),IFERROR(INDEX('BD PPA'!AD:AD,MATCH(1,('BD PPA'!U:U=B44)*('BD PPA'!AK:AK=$D$4),0)),INDEX('BD FRESCOS'!AD:AD,MATCH(1,('BD FRESCOS'!U:U=B44)*('BD FRESCOS'!AK:AK=$D$4),0)))),IF($B$4="SECOS",INDEX('BD SECOS'!X:X,MATCH(1,('BD SECOS'!Q:Q=B44)*('BD SECOS'!AE:AE=$D$4),0)),IF($B$4="PPA",INDEX('BD PPA'!AD:AD,MATCH(1,('BD PPA'!U:U=B44)*('BD PPA'!AK:AK=$D$4),0)),INDEX('BD FRESCOS'!AD:AD,MATCH(1,('BD FRESCOS'!U:U=B44)*('BD FRESCOS'!AK:AK=$D$4),0)))))),""))} -> RUTA 3 | J44: =IF(OR($B$8=0,B44=""),"",IF(AND(E44>20,G44>5),"⚠️ Muy lejos del CD y paraderos",IF(E44>20,"⚠️ Muy lejos del CD",IF(G44>5,"⚠️ Lejos de paraderos","📍 Normal")))) -> ⚠️ Muy lejos del CD
A45: =IF(OR($B$8=0,C45="",C45=0),"",7) -> 7 | B45: =IF($B$8=0,"",IFERROR(IF(INDEX(Distritos!$I$7:$I$66,MATCH(SMALL(Distritos!$J$7:$J$66,7),Distritos!$J$7:$J$66,0))=0,"",INDEX(Distritos!$H$7:$H$66,MATCH(SMALL(Distritos!$J$7:$J$66,7),Distritos!$J$7:$J$66,0))),"")) -> Los Olivos | C45: =IF($B$8=0,"",IFERROR(IF(INDEX(Distritos!$I$7:$I$66,MATCH(SMALL(Distritos!$J$7:$J$66,7),Distritos!$J$7:$J$66,0))=0,"",INDEX(Distritos!$I$7:$I$66,MATCH(SMALL(Distritos!$J$7:$J$66,7),Distritos!$J$7:$J$66,0))),"")) -> 6 | D45: =IF(OR($B$8=0,C45="",C45=0),"",C45/$B$8) -> 0.039215686 | E45: =IF(OR($B$8=0,B45=""),"",IFERROR(ROUND(IF($D$4="TODOS",IF($B$4="TODOS",(SUMIF('BD SECOS'!Q:Q,B45,'BD SECOS'!U:U)+SUMIF('BD PPA'!U:U,B45,'BD PPA'!AA:AA)+SUMIF('BD FRESCOS'!U:U,B45,'BD FRESCOS'!AA:AA))/(COUNTIF('BD SECOS'!Q:Q,B45)+COUNTIF('BD PPA'!U:U,B45)+COUNTIF('BD FRESCOS'!U:U,B45)),IF($B$4="SECOS",AVERAGEIF('BD SECOS'!Q:Q,B45,'BD SECOS'!U:U),IF($B$4="PPA",AVERAGEIF('BD PPA'!U:U,B45,'BD PPA'!AA:AA),AVERAGEIF('BD FRESCOS'!U:U,B45,'BD FRESCOS'!AA:AA)))),IF($B$4="TODOS",(SUMIFS('BD SECOS'!U:U,'BD SECOS'!Q:Q,B45,'BD SECOS'!AE:AE,$D$4)+SUMIFS('BD PPA'!AA:AA,'BD PPA'!U:U,B45,'BD PPA'!AK:AK,$D$4)+SUMIFS('BD FRESCOS'!AA:AA,'BD FRESCOS'!U:U,B45,'BD FRESCOS'!AK:AK,$D$4))/(COUNTIFS('BD SECOS'!Q:Q,B45,'BD SECOS'!AE:AE,$D$4)+COUNTIFS('BD PPA'!U:U,B45,'BD PPA'!AK:AK,$D$4)+COUNTIFS('BD FRESCOS'!U:U,B45,'BD FRESCOS'!AK:AK,$D$4)),IF($B$4="SECOS",AVERAGEIFS('BD SECOS'!U:U,'BD SECOS'!Q:Q,B45,'BD SECOS'!AE:AE,$D$4),IF($B$4="PPA",AVERAGEIFS('BD PPA'!AA:AA,'BD PPA'!U:U,B45,'BD PPA'!AK:AK,$D$4),AVERAGEIFS('BD FRESCOS'!AA:AA,'BD FRESCOS'!U:U,B45,'BD FRESCOS'!AK:AK,$D$4))))),2),"")) -> 18.88 | F45: =IF(OR($B$8=0,E45=""),"",IF(E45<=5,"🟢 Muy Cerca",IF(E45<=10,"🟡 Cerca",IF(E45<=20,"🟠 Moderada","🔴 Lejos")))) -> 🟠 Moderada | G45: =IF(OR($B$8=0,B45=""),"",IFERROR(ROUND(IF($D$4="TODOS",IF($B$4="TODOS",(SUMIF('BD SECOS'!Q:Q,B45,'BD SECOS'!Y:Y)+SUMIF('BD PPA'!U:U,B45,'BD PPA'!AE:AE)+SUMIF('BD FRESCOS'!U:U,B45,'BD FRESCOS'!AE:AE))/(COUNTIF('BD SECOS'!Q:Q,B45)+COUNTIF('BD PPA'!U:U,B45)+COUNTIF('BD FRESCOS'!U:U,B45)),IF($B$4="SECOS",AVERAGEIF('BD SECOS'!Q:Q,B45,'BD SECOS'!Y:Y),IF($B$4="PPA",AVERAGEIF('BD PPA'!U:U,B45,'BD PPA'!AE:AE),AVERAGEIF('BD FRESCOS'!U:U,B45,'BD FRESCOS'!AE:AE)))),IF($B$4="TODOS",(SUMIFS('BD SECOS'!Y:Y,'BD SECOS'!Q:Q,B45,'BD SECOS'!AE:AE,$D$4)+SUMIFS('BD PPA'!AE:AE,'BD PPA'!U:U,B45,'BD PPA'!AK:AK,$D$4)+SUMIFS('BD FRESCOS'!AE:AE,'BD FRESCOS'!U:U,B45,'BD FRESCOS'!AK:AK,$D$4))/(COUNTIFS('BD SECOS'!Q:Q,B45,'BD SECOS'!AE:AE,$D$4)+COUNTIFS('BD PPA'!U:U,B45,'BD PPA'!AK:AK,$D$4)+COUNTIFS('BD FRESCOS'!U:U,B45,'BD FRESCOS'!AK:AK,$D$4)),IF($B$4="SECOS",AVERAGEIFS('BD SECOS'!Y:Y,'BD SECOS'!Q:Q,B45,'BD SECOS'!AE:AE,$D$4),IF($B$4="PPA",AVERAGEIFS('BD PPA'!AE:AE,'BD PPA'!U:U,B45,'BD PPA'!AK:AK,$D$4),AVERAGEIFS('BD FRESCOS'!AE:AE,'BD FRESCOS'!U:U,B45,'BD FRESCOS'!AK:AK,$D$4))))),2),"")) -> 0.83 | H45: =IF(OR($B$8=0,G45=""),"",IF(G45<=1,"🟢 Muy Cerca",IF(G45<=3,"🟡 Cerca",IF(G45<=5,"🟠 Moderada","🔴 Lejos")))) -> 🟢 Muy Cerca | I45: {=IF(OR($B$8=0,B45=""),"",IFERROR(IF($D$4="TODOS",IF($B$4="TODOS",INDEX('BD SECOS'!X:X,MATCH(B45,'BD SECOS'!Q:Q,0)),IF($B$4="SECOS",INDEX('BD SECOS'!X:X,MATCH(B45,'BD SECOS'!Q:Q,0)),IF($B$4="PPA",INDEX('BD PPA'!AD:AD,MATCH(B45,'BD PPA'!U:U,0)),INDEX('BD FRESCOS'!AD:AD,MATCH(B45,'BD FRESCOS'!U:U,0))))),IF($B$4="TODOS",IFERROR(INDEX('BD SECOS'!X:X,MATCH(1,('BD SECOS'!Q:Q=B45)*('BD SECOS'!AE:AE=$D$4),0)),IFERROR(INDEX('BD PPA'!AD:AD,MATCH(1,('BD PPA'!U:U=B45)*('BD PPA'!AK:AK=$D$4),0)),INDEX('BD FRESCOS'!AD:AD,MATCH(1,('BD FRESCOS'!U:U=B45)*('BD FRESCOS'!AK:AK=$D$4),0)))),IF($B$4="SECOS",INDEX('BD SECOS'!X:X,MATCH(1,('BD SECOS'!Q:Q=B45)*('BD SECOS'!AE:AE=$D$4),0)),IF($B$4="PPA",INDEX('BD PPA'!AD:AD,MATCH(1,('BD PPA'!U:U=B45)*('BD PPA'!AK:AK=$D$4),0)),INDEX('BD FRESCOS'!AD:AD,MATCH(1,('BD FRESCOS'!U:U=B45)*('BD FRESCOS'!AK:AK=$D$4),0)))))),""))} -> RUTA 7 | J45: =IF(OR($B$8=0,B45=""),"",IF(AND(E45>20,G45>5),"⚠️ Muy lejos del CD y paraderos",IF(E45>20,"⚠️ Muy lejos del CD",IF(G45>5,"⚠️ Lejos de paraderos","📍 Normal")))) -> 📍 Normal
A46: =IF(OR($B$8=0,C46="",C46=0),"",8) -> 8 | B46: =IF($B$8=0,"",IFERROR(IF(INDEX(Distritos!$I$7:$I$66,MATCH(SMALL(Distritos!$J$7:$J$66,8),Distritos!$J$7:$J$66,0))=0,"",INDEX(Distritos!$H$7:$H$66,MATCH(SMALL(Distritos!$J$7:$J$66,8),Distritos!$J$7:$J$66,0))),"")) -> Carabayllo | C46: =IF($B$8=0,"",IFERROR(IF(INDEX(Distritos!$I$7:$I$66,MATCH(SMALL(Distritos!$J$7:$J$66,8),Distritos!$J$7:$J$66,0))=0,"",INDEX(Distritos!$I$7:$I$66,MATCH(SMALL(Distritos!$J$7:$J$66,8),Distritos!$J$7:$J$66,0))),"")) -> 4 | D46: =IF(OR($B$8=0,C46="",C46=0),"",C46/$B$8) -> 0.026143791 | E46: =IF(OR($B$8=0,B46=""),"",IFERROR(ROUND(IF($D$4="TODOS",IF($B$4="TODOS",(SUMIF('BD SECOS'!Q:Q,B46,'BD SECOS'!U:U)+SUMIF('BD PPA'!U:U,B46,'BD PPA'!AA:AA)+SUMIF('BD FRESCOS'!U:U,B46,'BD FRESCOS'!AA:AA))/(COUNTIF('BD SECOS'!Q:Q,B46)+COUNTIF('BD PPA'!U:U,B46)+COUNTIF('BD FRESCOS'!U:U,B46)),IF($B$4="SECOS",AVERAGEIF('BD SECOS'!Q:Q,B46,'BD SECOS'!U:U),IF($B$4="PPA",AVERAGEIF('BD PPA'!U:U,B46,'BD PPA'!AA:AA),AVERAGEIF('BD FRESCOS'!U:U,B46,'BD FRESCOS'!AA:AA)))),IF($B$4="TODOS",(SUMIFS('BD SECOS'!U:U,'BD SECOS'!Q:Q,B46,'BD SECOS'!AE:AE,$D$4)+SUMIFS('BD PPA'!AA:AA,'BD PPA'!U:U,B46,'BD PPA'!AK:AK,$D$4)+SUMIFS('BD FRESCOS'!AA:AA,'BD FRESCOS'!U:U,B46,'BD FRESCOS'!AK:AK,$D$4))/(COUNTIFS('BD SECOS'!Q:Q,B46,'BD SECOS'!AE:AE,$D$4)+COUNTIFS('BD PPA'!U:U,B46,'BD PPA'!AK:AK,$D$4)+COUNTIFS('BD FRESCOS'!U:U,B46,'BD FRESCOS'!AK:AK,$D$4)),IF($B$4="SECOS",AVERAGEIFS('BD SECOS'!U:U,'BD SECOS'!Q:Q,B46,'BD SECOS'!AE:AE,$D$4),IF($B$4="PPA",AVERAGEIFS('BD PPA'!AA:AA,'BD PPA'!U:U,B46,'BD PPA'!AK:AK,$D$4),AVERAGEIFS('BD FRESCOS'!AA:AA,'BD FRESCOS'!U:U,B46,'BD FRESCOS'!AK:AK,$D$4))))),2),"")) -> 20.41 | F46: =IF(OR($B$8=0,E46=""),"",IF(E46<=5,"🟢 Muy Cerca",IF(E46<=10,"🟡 Cerca",IF(E46<=20,"🟠 Moderada","🔴 Lejos")))) -> 🔴 Lejos | G46: =IF(OR($B$8=0,B46=""),"",IFERROR(ROUND(IF($D$4="TODOS",IF($B$4="TODOS",(SUMIF('BD SECOS'!Q:Q,B46,'BD SECOS'!Y:Y)+SUMIF('BD PPA'!U:U,B46,'BD PPA'!AE:AE)+SUMIF('BD FRESCOS'!U:U,B46,'BD FRESCOS'!AE:AE))/(COUNTIF('BD SECOS'!Q:Q,B46)+COUNTIF('BD PPA'!U:U,B46)+COUNTIF('BD FRESCOS'!U:U,B46)),IF($B$4="SECOS",AVERAGEIF('BD SECOS'!Q:Q,B46,'BD SECOS'!Y:Y),IF($B$4="PPA",AVERAGEIF('BD PPA'!U:U,B46,'BD PPA'!AE:AE),AVERAGEIF('BD FRESCOS'!U:U,B46,'BD FRESCOS'!AE:AE)))),IF($B$4="TODOS",(SUMIFS('BD SECOS'!Y:Y,'BD SECOS'!Q:Q,B46,'BD SECOS'!AE:AE,$D$4)+SUMIFS('BD PPA'!AE:AE,'BD PPA'!U:U,B46,'BD PPA'!AK:AK,$D$4)+SUMIFS('BD FRESCOS'!AE:AE,'BD FRESCOS'!U:U,B46,'BD FRESCOS'!AK:AK,$D$4))/(COUNTIFS('BD SECOS'!Q:Q,B46,'BD SECOS'!AE:AE,$D$4)+COUNTIFS('BD PPA'!U:U,B46,'BD PPA'!AK:AK,$D$4)+COUNTIFS('BD FRESCOS'!U:U,B46,'BD FRESCOS'!AK:AK,$D$4)),IF($B$4="SECOS",AVERAGEIFS('BD SECOS'!Y:Y,'BD SECOS'!Q:Q,B46,'BD SECOS'!AE:AE,$D$4),IF($B$4="PPA",AVERAGEIFS('BD PPA'!AE:AE,'BD PPA'!U:U,B46,'BD PPA'!AK:AK,$D$4),AVERAGEIFS('BD FRESCOS'!AE:AE,'BD FRESCOS'!U:U,B46,'BD FRESCOS'!AK:AK,$D$4))))),2),"")) -> 5.62 | H46: =IF(OR($B$8=0,G46=""),"",IF(G46<=1,"🟢 Muy Cerca",IF(G46<=3,"🟡 Cerca",IF(G46<=5,"🟠 Moderada","🔴 Lejos")))) -> 🔴 Lejos | I46: {=IF(OR($B$8=0,B46=""),"",IFERROR(IF($D$4="TODOS",IF($B$4="TODOS",INDEX('BD SECOS'!X:X,MATCH(B46,'BD SECOS'!Q:Q,0)),IF($B$4="SECOS",INDEX('BD SECOS'!X:X,MATCH(B46,'BD SECOS'!Q:Q,0)),IF($B$4="PPA",INDEX('BD PPA'!AD:AD,MATCH(B46,'BD PPA'!U:U,0)),INDEX('BD FRESCOS'!AD:AD,MATCH(B46,'BD FRESCOS'!U:U,0))))),IF($B$4="TODOS",IFERROR(INDEX('BD SECOS'!X:X,MATCH(1,('BD SECOS'!Q:Q=B46)*('BD SECOS'!AE:AE=$D$4),0)),IFERROR(INDEX('BD PPA'!AD:AD,MATCH(1,('BD PPA'!U:U=B46)*('BD PPA'!AK:AK=$D$4),0)),INDEX('BD FRESCOS'!AD:AD,MATCH(1,('BD FRESCOS'!U:U=B46)*('BD FRESCOS'!AK:AK=$D$4),0)))),IF($B$4="SECOS",INDEX('BD SECOS'!X:X,MATCH(1,('BD SECOS'!Q:Q=B46)*('BD SECOS'!AE:AE=$D$4),0)),IF($B$4="PPA",INDEX('BD PPA'!AD:AD,MATCH(1,('BD PPA'!U:U=B46)*('BD PPA'!AK:AK=$D$4),0)),INDEX('BD FRESCOS'!AD:AD,MATCH(1,('BD FRESCOS'!U:U=B46)*('BD FRESCOS'!AK:AK=$D$4),0)))))),""))} -> RUTA 4B | J46: =IF(OR($B$8=0,B46=""),"",IF(AND(E46>20,G46>5),"⚠️ Muy lejos del CD y paraderos",IF(E46>20,"⚠️ Muy lejos del CD",IF(G46>5,"⚠️ Lejos de paraderos","📍 Normal")))) -> ⚠️ Muy lejos del CD y paraderos
A47: =IF(OR($B$8=0,C47="",C47=0),"",9) -> 9 | B47: =IF($B$8=0,"",IFERROR(IF(INDEX(Distritos!$I$7:$I$66,MATCH(SMALL(Distritos!$J$7:$J$66,9),Distritos!$J$7:$J$66,0))=0,"",INDEX(Distritos!$H$7:$H$66,MATCH(SMALL(Distritos!$J$7:$J$66,9),Distritos!$J$7:$J$66,0))),"")) -> Chaclacayo | C47: =IF($B$8=0,"",IFERROR(IF(INDEX(Distritos!$I$7:$I$66,MATCH(SMALL(Distritos!$J$7:$J$66,9),Distritos!$J$7:$J$66,0))=0,"",INDEX(Distritos!$I$7:$I$66,MATCH(SMALL(Distritos!$J$7:$J$66,9),Distritos!$J$7:$J$66,0))),"")) -> 4 | D47: =IF(OR($B$8=0,C47="",C47=0),"",C47/$B$8) -> 0.026143791 | E47: =IF(OR($B$8=0,B47=""),"",IFERROR(ROUND(IF($D$4="TODOS",IF($B$4="TODOS",(SUMIF('BD SECOS'!Q:Q,B47,'BD SECOS'!U:U)+SUMIF('BD PPA'!U:U,B47,'BD PPA'!AA:AA)+SUMIF('BD FRESCOS'!U:U,B47,'BD FRESCOS'!AA:AA))/(COUNTIF('BD SECOS'!Q:Q,B47)+COUNTIF('BD PPA'!U:U,B47)+COUNTIF('BD FRESCOS'!U:U,B47)),IF($B$4="SECOS",AVERAGEIF('BD SECOS'!Q:Q,B47,'BD SECOS'!U:U),IF($B$4="PPA",AVERAGEIF('BD PPA'!U:U,B47,'BD PPA'!AA:AA),AVERAGEIF('BD FRESCOS'!U:U,B47,'BD FRESCOS'!AA:AA)))),IF($B$4="TODOS",(SUMIFS('BD SECOS'!U:U,'BD SECOS'!Q:Q,B47,'BD SECOS'!AE:AE,$D$4)+SUMIFS('BD PPA'!AA:AA,'BD PPA'!U:U,B47,'BD PPA'!AK:AK,$D$4)+SUMIFS('BD FRESCOS'!AA:AA,'BD FRESCOS'!U:U,B47,'BD FRESCOS'!AK:AK,$D$4))/(COUNTIFS('BD SECOS'!Q:Q,B47,'BD SECOS'!AE:AE,$D$4)+COUNTIFS('BD PPA'!U:U,B47,'BD PPA'!AK:AK,$D$4)+COUNTIFS('BD FRESCOS'!U:U,B47,'BD FRESCOS'!AK:AK,$D$4)),IF($B$4="SECOS",AVERAGEIFS('BD SECOS'!U:U,'BD SECOS'!Q:Q,B47,'BD SECOS'!AE:AE,$D$4),IF($B$4="PPA",AVERAGEIFS('BD PPA'!AA:AA,'BD PPA'!U:U,B47,'BD PPA'!AK:AK,$D$4),AVERAGEIFS('BD FRESCOS'!AA:AA,'BD FRESCOS'!U:U,B47,'BD FRESCOS'!AK:AK,$D$4))))),2),"")) -> 10.41 | F47: =IF(OR($B$8=0,E47=""),"",IF(E47<=5,"🟢 Muy Cerca",IF(E47<=10,"🟡 Cerca",IF(E47<=20,"🟠 Moderada","🔴 Lejos")))) -> 🟠 Moderada | G47: =IF(OR($B$8=0,B47=""),"",IFERROR(ROUND(IF($D$4="TODOS",IF($B$4="TODOS",(SUMIF('BD SECOS'!Q:Q,B47,'BD SECOS'!Y:Y)+SUMIF('BD PPA'!U:U,B47,'BD PPA'!AE:AE)+SUMIF('BD FRESCOS'!U:U,B47,'BD FRESCOS'!AE:AE))/(COUNTIF('BD SECOS'!Q:Q,B47)+COUNTIF('BD PPA'!U:U,B47)+COUNTIF('BD FRESCOS'!U:U,B47)),IF($B$4="SECOS",AVERAGEIF('BD SECOS'!Q:Q,B47,'BD SECOS'!Y:Y),IF($B$4="PPA",AVERAGEIF('BD PPA'!U:U,B47,'BD PPA'!AE:AE),AVERAGEIF('BD FRESCOS'!U:U,B47,'BD FRESCOS'!AE:AE)))),IF($B$4="TODOS",(SUMIFS('BD SECOS'!Y:Y,'BD SECOS'!Q:Q,B47,'BD SECOS'!AE:AE,$D$4)+SUMIFS('BD PPA'!AE:AE,'BD PPA'!U:U,B47,'BD PPA'!AK:AK,$D$4)+SUMIFS('BD FRESCOS'!AE:AE,'BD FRESCOS'!U:U,B47,'BD FRESCOS'!AK:AK,$D$4))/(COUNTIFS('BD SECOS'!Q:Q,B47,'BD SECOS'!AE:AE,$D$4)+COUNTIFS('BD PPA'!U:U,B47,'BD PPA'!AK:AK,$D$4)+COUNTIFS('BD FRESCOS'!U:U,B47,'BD FRESCOS'!AK:AK,$D$4)),IF($B$4="SECOS",AVERAGEIFS('BD SECOS'!Y:Y,'BD SECOS'!Q:Q,B47,'BD SECOS'!AE:AE,$D$4),IF($B$4="PPA",AVERAGEIFS('BD PPA'!AE:AE,'BD PPA'!U:U,B47,'BD PPA'!AK:AK,$D$4),AVERAGEIFS('BD FRESCOS'!AE:AE,'BD FRESCOS'!U:U,B47,'BD FRESCOS'!AK:AK,$D$4))))),2),"")) -> 0.84 | H47: =IF(OR($B$8=0,G47=""),"",IF(G47<=1,"🟢 Muy Cerca",IF(G47<=3,"🟡 Cerca",IF(G47<=5,"🟠 Moderada","🔴 Lejos")))) -> 🟢 Muy Cerca | I47: {=IF(OR($B$8=0,B47=""),"",IFERROR(IF($D$4="TODOS",IF($B$4="TODOS",INDEX('BD SECOS'!X:X,MATCH(B47,'BD SECOS'!Q:Q,0)),IF($B$4="SECOS",INDEX('BD SECOS'!X:X,MATCH(B47,'BD SECOS'!Q:Q,0)),IF($B$4="PPA",INDEX('BD PPA'!AD:AD,MATCH(B47,'BD PPA'!U:U,0)),INDEX('BD FRESCOS'!AD:AD,MATCH(B47,'BD FRESCOS'!U:U,0))))),IF($B$4="TODOS",IFERROR(INDEX('BD SECOS'!X:X,MATCH(1,('BD SECOS'!Q:Q=B47)*('BD SECOS'!AE:AE=$D$4),0)),IFERROR(INDEX('BD PPA'!AD:AD,MATCH(1,('BD PPA'!U:U=B47)*('BD PPA'!AK:AK=$D$4),0)),INDEX('BD FRESCOS'!AD:AD,MATCH(1,('BD FRESCOS'!U:U=B47)*('BD FRESCOS'!AK:AK=$D$4),0)))),IF($B$4="SECOS",INDEX('BD SECOS'!X:X,MATCH(1,('BD SECOS'!Q:Q=B47)*('BD SECOS'!AE:AE=$D$4),0)),IF($B$4="PPA",INDEX('BD PPA'!AD:AD,MATCH(1,('BD PPA'!U:U=B47)*('BD PPA'!AK:AK=$D$4),0)),INDEX('BD FRESCOS'!AD:AD,MATCH(1,('BD FRESCOS'!U:U=B47)*('BD FRESCOS'!AK:AK=$D$4),0)))))),""))} -> RUTA 5A | J47: =IF(OR($B$8=0,B47=""),"",IF(AND(E47>20,G47>5),"⚠️ Muy lejos del CD y paraderos",IF(E47>20,"⚠️ Muy lejos del CD",IF(G47>5,"⚠️ Lejos de paraderos","📍 Normal")))) -> 📍 Normal
